Workbook

Sheet Introduction
B4: Financial Model — 5-Year Projections and Valuation
B5: Prepared for [Client Name]
B9: Prepared by | F9: Version / Date | J9: Currency / Units
B10: Dhananjay Anil Raut | F10: v1.0 — July 2026 | J10: AED — Monthly build, yearly summary
B13: Color Legend
B15: 123 | C15: Input cell — safe to change (gray-blue fill, navy bold font)
B16: 123 | C16: Formula cell — do not edit (white, black font)
B17: 123 | C17: Cross-sheet link (green font)
B18: -1 | C18: Error / check flag (red — investigate immediately)
B21: Workbook Tabs
B22: Assumptions → Revenue Buildup → Cost Buildup → FAS → IS → BS → CFS → Valuation
B25: Disclaimer: These are estimates provided to the best of our knowledge based on logical assumptions and current market conditions; actual results may vary materially.

Sheet Assumptions
A1: Assumptions
A2: Cells in Orange are assumptions | M2: MONTHLY | BV2: YEARLY
A3: Year | M3: 1 | N3: 1 | O3: 1 | P3: 1 | Q3: 1 | R3: 1 | S3: 1 | T3: 1 | U3: 1 | V3: 1 | W3: 1 | X3: 1 | Y3: =X3+1 -> 2 | Z3: =Y3 -> 2 | AA3: =Z3 -> 2 | AB3: =AA3 -> 2 | AC3: =AB3 -> 2 | AD3: =AC3 -> 2 | AE3: =AD3 -> 2 | AF3: =AE3 -> 2 | AG3: =AF3 -> 2 | ... AJ3: =AI3 -> 2 | AK3: 3 | AL3: 3 | AM3: 3 | AN3: 3 | AO3: 3 | AP3: 3 | AQ3: 3 | AR3: 3 | AS3: 3 | AT3: 3 | AU3: 3 | AV3: 3 | AW3: 4 | AX3: 4 | AY3: 4 | AZ3: 4 | BA3: 4 | BB3: 4 | BC3: 4 | BD3: 4 | BE3: 4 | BF3: 4 | BG3: 4 | BH3: 4 | BI3: 5 | BJ3: 5 | BK3: 5 | BL3: 5 | BM3: 5 | BN3: 5 | BO3: 5 | BP3: 5 | BQ3: 5 | BR3: 5 | BS3: 5 | BT3: 5 | BV3: 1 | BW3: 2 | BX3: 3 | BY3: 4 | BZ3: 5
A4: Months | M4: 1 | N4: =M4+1 -> 2 | O4: =N4+1 -> 3 | P4: =O4+1 -> 4 | Q4: =P4+1 -> 5 | R4: =Q4+1 -> 6 | S4: =R4+1 -> 7 | T4: =S4+1 -> 8 | U4: =T4+1 -> 9 | ... BT4: =BS4+1 -> 60 | BV4: 12 | BW4: 24 | BX4: 36 | BY4: 48 | BZ4: 60
A5: General Assumptions
A6: Base Currency | G6: USD
A7: INR:USD | F7: as on 25/05/25 | G7: 85.17
A8: Revenue Assumptions
A9: Existing Clients | G9: 1
A10: New Clients | M10: 0 | N10: 0 | O10: 1 | P10: 0 | Q10: 0 | R10: 1 | S10: 0 | T10: 0 | U10: 1 | V10: 0 | W10: 0 | X10: 1 | Y10: 0 | Z10: 0 | AA10: 1 | AB10: 0 | AC10: 0 | AD10: 1 | AE10: 0 | AF10: 0 | AG10: 1 | AH10: 0 | AI10: 0 | AJ10: 1 | AK10: 0 | AL10: 0 | AM10: 0 | AN10: 0 | AO10: 0 | AP10: 1 | AQ10: 0 | AR10: 0 | AS10: 0 | AT10: 0 | AU10: 0 | AV10: 1 | AW10: 0 | AX10: 0 | AY10: 0 | AZ10: 1 | BA10: 0 | BB10: 0 | BC10: 0 | BD10: 1 | BE10: 0 | BF10: 0 | BG10: 0 | BH10: 1 | BI10: 0 | BJ10: 1 | BK10: 0 | BL10: 1 | BM10: 0 | BN10: 1 | BO10: 0 | BP10: 1 | BQ10: 0 | BR10: 1 | BS10: 0 | BT10: 1 | BV10: =SUMIF($M$3:$BT$3,BV$3,$M10:$BT10) -> 4 | BW10: =SUMIF($M$3:$BT$3,BW$3,$M10:$BT10) -> 4 | BX10: =SUMIF($M$3:$BT$3,BX$3,$M10:$BT10) -> 2 | BY10: =SUMIF($M$3:$BT$3,BY$3,$M10:$BT10) -> 3 | BZ10: =SUMIF($M$3:$BT$3,BZ$3,$M10:$BT10) -> 6
A11: Annual SaaS Subscription Price (Median Price) | F11: USD | G11: 75000 | H11: =G11 -> 75000 | M11: =G11 -> 75000 | N11: =M11+($H11-$G11)/COUNT($N$4:$BT$4) -> 75000 | O11: =N11+($H11-$G11)/COUNT($N$4:$BT$4) -> 75000 | P11: =O11+($H11-$G11)/COUNT($N$4:$BT$4) -> 75000 | Q11: =P11+($H11-$G11)/COUNT($N$4:$BT$4) -> 75000 | R11: =Q11+($H11-$G11)/COUNT($N$4:$BT$4) -> 75000 | S11: =R11+($H11-$G11)/COUNT($N$4:$BT$4) -> 75000 | T11: =S11+($H11-$G11)/COUNT($N$4:$BT$4) -> 75000 | U11: =T11+($H11-$G11)/COUNT($N$4:$BT$4) -> 75000 | ... BT11: =BS11+($H11-$G11)/COUNT($N$4:$BT$4) -> 75000
A12: Duration of Contract | F12: Months | G12: 12 | H12: 12 | M12: =G12 -> 12 | N12: =M12+($H12-$G12)/COUNT($N$4:$BT$4) -> 12 | O12: =N12+($H12-$G12)/COUNT($N$4:$BT$4) -> 12 | P12: =O12+($H12-$G12)/COUNT($N$4:$BT$4) -> 12 | Q12: =P12+($H12-$G12)/COUNT($N$4:$BT$4) -> 12 | R12: =Q12+($H12-$G12)/COUNT($N$4:$BT$4) -> 12 | S12: =R12+($H12-$G12)/COUNT($N$4:$BT$4) -> 12 | T12: =S12+($H12-$G12)/COUNT($N$4:$BT$4) -> 12 | U12: =T12+($H12-$G12)/COUNT($N$4:$BT$4) -> 12 | ... BT12: =BS12+($H12-$G12)/COUNT($N$4:$BT$4) -> 12
A13: Churn & Expansion Revenue
A14: Annual Churn Rate | F14: % | G14: 0.1 | H14: 0.1 | M14: =G14 -> 0.1 | N14: =M14+($H14-$G14)/COUNT($N$4:$BT$4) -> 0.1 | O14: =N14+($H14-$G14)/COUNT($N$4:$BT$4) -> 0.1 | P14: =O14+($H14-$G14)/COUNT($N$4:$BT$4) -> 0.1 | Q14: =P14+($H14-$G14)/COUNT($N$4:$BT$4) -> 0.1 | R14: =Q14+($H14-$G14)/COUNT($N$4:$BT$4) -> 0.1 | S14: =R14+($H14-$G14)/COUNT($N$4:$BT$4) -> 0.1 | T14: =S14+($H14-$G14)/COUNT($N$4:$BT$4) -> 0.1 | U14: =T14+($H14-$G14)/COUNT($N$4:$BT$4) -> 0.1 | ... BT14: =BS14+($H14-$G14)/COUNT($N$4:$BT$4) -> 0.1
A15: Recurring Contracts | F15: % | G15: =1-G14 -> 0.9 | H15: =1-H14 -> 0.9 | M15: =G15 -> 0.9 | N15: =M15+($H15-$G15)/COUNT($N$4:$BT$4) -> 0.9 | O15: =N15+($H15-$G15)/COUNT($N$4:$BT$4) -> 0.9 | P15: =O15+($H15-$G15)/COUNT($N$4:$BT$4) -> 0.9 | Q15: =P15+($H15-$G15)/COUNT($N$4:$BT$4) -> 0.9 | R15: =Q15+($H15-$G15)/COUNT($N$4:$BT$4) -> 0.9 | S15: =R15+($H15-$G15)/COUNT($N$4:$BT$4) -> 0.9 | T15: =S15+($H15-$G15)/COUNT($N$4:$BT$4) -> 0.9 | U15: =T15+($H15-$G15)/COUNT($N$4:$BT$4) -> 0.9 | ... BT15: =BS15+($H15-$G15)/COUNT($N$4:$BT$4) -> 0.9
A16: Cost Assumptions
A17: Direct Cost
A18: Hosting & Infrastructure Costs
A19: Hosting & Infrastructure Costs | F19: as % of revenue | G19: 0.06 | H19: =G19 -> 0.06 | M19: =G19 -> 0.06 | N19: =M19+($H19-$G19)/COUNT($N$4:$BT$4) -> 0.06 | O19: =N19+($H19-$G19)/COUNT($N$4:$BT$4) -> 0.06 | P19: =O19+($H19-$G19)/COUNT($N$4:$BT$4) -> 0.06 | Q19: =P19+($H19-$G19)/COUNT($N$4:$BT$4) -> 0.06 | R19: =Q19+($H19-$G19)/COUNT($N$4:$BT$4) -> 0.06 | S19: =R19+($H19-$G19)/COUNT($N$4:$BT$4) -> 0.06 | T19: =S19+($H19-$G19)/COUNT($N$4:$BT$4) -> 0.06 | U19: =T19+($H19-$G19)/COUNT($N$4:$BT$4) -> 0.06 | ... BT19: =BS19+($H19-$G19)/COUNT($N$4:$BT$4) -> 0.06 | BV19: =SUMIF($M$3:$BT$3,BV$3,$M19:$BT19) -> 0.72 | BW19: =SUMIF($M$3:$BT$3,BW$3,$M19:$BT19) -> 0.72 | BX19: =SUMIF($M$3:$BT$3,BX$3,$M19:$BT19) -> 0.72 | BY19: =SUMIF($M$3:$BT$3,BY$3,$M19:$BT19) -> 0.72 | BZ19: =SUMIF($M$3:$BT$3,BZ$3,$M19:$BT19) -> 0.72
A20: Third-Party Software & API Costs
A21: Payment gateway/ Bank Charges | F21: as a % of bookings | G21: 0 | H21: 0 | M21: =G21 -> 0 | N21: =M21+($H21-$G21)/COUNT($N$4:$BT$4) -> 0 | O21: =N21+($H21-$G21)/COUNT($N$4:$BT$4) -> 0 | P21: =O21+($H21-$G21)/COUNT($N$4:$BT$4) -> 0 | Q21: =P21+($H21-$G21)/COUNT($N$4:$BT$4) -> 0 | R21: =Q21+($H21-$G21)/COUNT($N$4:$BT$4) -> 0 | S21: =R21+($H21-$G21)/COUNT($N$4:$BT$4) -> 0 | T21: =S21+($H21-$G21)/COUNT($N$4:$BT$4) -> 0 | U21: =T21+($H21-$G21)/COUNT($N$4:$BT$4) -> 0 | ... BT21: =BS21+($H21-$G21)/COUNT($N$4:$BT$4) -> 0
A22: Headcount
A23: Customer Support | F23: Customer support/Account | G23: 5 | H23: 5 | M23: =G23 -> 5 | N23: =M23+($H23-$G23)/COUNT($N$4:$BT$4) -> 5 | O23: =N23+($H23-$G23)/COUNT($N$4:$BT$4) -> 5 | P23: =O23+($H23-$G23)/COUNT($N$4:$BT$4) -> 5 | Q23: =P23+($H23-$G23)/COUNT($N$4:$BT$4) -> 5 | R23: =Q23+($H23-$G23)/COUNT($N$4:$BT$4) -> 5 | S23: =R23+($H23-$G23)/COUNT($N$4:$BT$4) -> 5 | T23: =S23+($H23-$G23)/COUNT($N$4:$BT$4) -> 5 | U23: =T23+($H23-$G23)/COUNT($N$4:$BT$4) -> 5 | ... BT23: =BS23+($H23-$G23)/COUNT($N$4:$BT$4) -> 5
A24: Customer Support | F24: Monthly Salary | G24: =70000/$G$7 -> 821.88564 | H24: 0.05 | I24: Annual Increment
A25: Operating Expense
A26: Sales & Marketing Expense
A27: Sales
A28: Sales-SDR-Outsourced | F28: Monthly expense | G28: 1800 | H28: 0 | I28: Annual Increment | M28: =G28 -> 1800 | N28: =M28*(1+$H$28) -> 1800 | O28: =N28*(1+$H$28) -> 1800 | P28: =O28*(1+$H$28) -> 1800 | Q28: =P28*(1+$H$28) -> 1800 | R28: =Q28*(1+$H$28) -> 1800 | S28: =R28*(1+$H$28) -> 1800 | T28: =S28*(1+$H$28) -> 1800 | U28: =T28*(1+$H$28) -> 1800 | ... BT28: =BS28*(1+$H$28) -> 1800
A29: Cost/Lead | F29: 300-300$/qualified lead | G29: 300 | H29: =G29 -> 300 | M29: =G29 -> 300 | N29: =M29+($H29-$G29)/COUNT($N$4:$BT$4) -> 300 | O29: =N29+($H29-$G29)/COUNT($N$4:$BT$4) -> 300 | P29: =O29+($H29-$G29)/COUNT($N$4:$BT$4) -> 300 | Q29: =P29+($H29-$G29)/COUNT($N$4:$BT$4) -> 300 | R29: =Q29+($H29-$G29)/COUNT($N$4:$BT$4) -> 300 | S29: =R29+($H29-$G29)/COUNT($N$4:$BT$4) -> 300 | T29: =S29+($H29-$G29)/COUNT($N$4:$BT$4) -> 300 | U29: =T29+($H29-$G29)/COUNT($N$4:$BT$4) -> 300 | ... BT29: =BS29+($H29-$G29)/COUNT($N$4:$BT$4) -> 300 | BV29: =SUMIF($M$3:$BT$3,BV$3,$M28:$BT28) -> 21600 | BW29: =SUMIF($M$3:$BT$3,BW$3,$M28:$BT28) -> 21600 | BX29: =SUMIF($M$3:$BT$3,BX$3,$M28:$BT28) -> 21600 | BY29: =SUMIF($M$3:$BT$3,BY$3,$M28:$BT28) -> 21600 | BZ29: =SUMIF($M$3:$BT$3,BZ$3,$M28:$BT28) -> 21600
A30: Additional Cost for Qualified Leads | G30: 300 | H30: =G30 -> 300 | M30: =G30 -> 300 | N30: =M30+($H30-$G30)/COUNT($N$4:$BT$4) -> 300 | O30: =N30+($H30-$G30)/COUNT($N$4:$BT$4) -> 300 | P30: =O30+($H30-$G30)/COUNT($N$4:$BT$4) -> 300 | Q30: =P30+($H30-$G30)/COUNT($N$4:$BT$4) -> 300 | R30: =Q30+($H30-$G30)/COUNT($N$4:$BT$4) -> 300 | S30: =R30+($H30-$G30)/COUNT($N$4:$BT$4) -> 300 | T30: =S30+($H30-$G30)/COUNT($N$4:$BT$4) -> 300 | U30: =T30+($H30-$G30)/COUNT($N$4:$BT$4) -> 300 | ... BT30: =BS30+($H30-$G30)/COUNT($N$4:$BT$4) -> 300
A31: Sales Commission %
A32: New Bookings | F32: as a % respective bookings | G32: 0.03 | H32: =G32 -> 0.03 | M32: =G32 -> 0.03 | N32: =M32+($H32-$G32)/COUNT($N$4:$BT$4) -> 0.03 | O32: =N32+($H32-$G32)/COUNT($N$4:$BT$4) -> 0.03 | P32: =O32+($H32-$G32)/COUNT($N$4:$BT$4) -> 0.03 | Q32: =P32+($H32-$G32)/COUNT($N$4:$BT$4) -> 0.03 | R32: =Q32+($H32-$G32)/COUNT($N$4:$BT$4) -> 0.03 | S32: =R32+($H32-$G32)/COUNT($N$4:$BT$4) -> 0.03 | T32: =S32+($H32-$G32)/COUNT($N$4:$BT$4) -> 0.03 | U32: =T32+($H32-$G32)/COUNT($N$4:$BT$4) -> 0.03 | ... BT32: =BS32+($H32-$G32)/COUNT($N$4:$BT$4) -> 0.03
A33: Renewals | F33: as a % respective bookings | G33: 0 | H33: 0 | M33: =G33 -> 0 | N33: =M33+($H33-$G33)/COUNT($N$4:$BT$4) -> 0 | O33: =N33+($H33-$G33)/COUNT($N$4:$BT$4) -> 0 | P33: =O33+($H33-$G33)/COUNT($N$4:$BT$4) -> 0 | Q33: =P33+($H33-$G33)/COUNT($N$4:$BT$4) -> 0 | R33: =Q33+($H33-$G33)/COUNT($N$4:$BT$4) -> 0 | S33: =R33+($H33-$G33)/COUNT($N$4:$BT$4) -> 0 | T33: =S33+($H33-$G33)/COUNT($N$4:$BT$4) -> 0 | U33: =T33+($H33-$G33)/COUNT($N$4:$BT$4) -> 0 | ... BT33: =BS33+($H33-$G33)/COUNT($N$4:$BT$4) -> 0
A34: Expansion | F34: as a % respective bookings | G34: 0 | H34: 0 | M34: =G34 -> 0 | N34: =M34+($H34-$G34)/COUNT($N$4:$BT$4) -> 0 | O34: =N34+($H34-$G34)/COUNT($N$4:$BT$4) -> 0 | P34: =O34+($H34-$G34)/COUNT($N$4:$BT$4) -> 0 | Q34: =P34+($H34-$G34)/COUNT($N$4:$BT$4) -> 0 | R34: =Q34+($H34-$G34)/COUNT($N$4:$BT$4) -> 0 | S34: =R34+($H34-$G34)/COUNT($N$4:$BT$4) -> 0 | T34: =S34+($H34-$G34)/COUNT($N$4:$BT$4) -> 0 | U34: =T34+($H34-$G34)/COUNT($N$4:$BT$4) -> 0 | ... BT34: =BS34+($H34-$G34)/COUNT($N$4:$BT$4) -> 0
A35: Sales Team-Headcount
A36: Client Success Manager | F36: Qualified Leads/CSM/Month | G36: 10 | H36: 10 | M36: =G36 -> 10 | N36: =M36+($H36-$G36)/COUNT($N$4:$BT$4) -> 10 | O36: =N36+($H36-$G36)/COUNT($N$4:$BT$4) -> 10 | P36: =O36+($H36-$G36)/COUNT($N$4:$BT$4) -> 10 | Q36: =P36+($H36-$G36)/COUNT($N$4:$BT$4) -> 10 | R36: =Q36+($H36-$G36)/COUNT($N$4:$BT$4) -> 10 | S36: =R36+($H36-$G36)/COUNT($N$4:$BT$4) -> 10 | T36: =S36+($H36-$G36)/COUNT($N$4:$BT$4) -> 10 | U36: =T36+($H36-$G36)/COUNT($N$4:$BT$4) -> 10 | ... BT36: =BS36+($H36-$G36)/COUNT($N$4:$BT$4) -> 10
A37: XYZ(For any additional role)
A38: Sales Team Salaries
A39: =A36 -> Client Success Manager | F39: Monthly Salary/Headcount | G39: 1200 | H39: 0.05 | I39: Annual Increment
F40: Monthly Salary/Headcount | G40: 0 | H40: 0.05 | I40: Annual Increment
...

Sheet Revenue Buildup
A1: Revenue Buildup
A2: Cells in Orange are assumptions | M2: MONTHLY | BV2: YEARLY
A3: Year | M3: 1 | N3: 1 | O3: 1 | P3: 1 | Q3: 1 | R3: 1 | S3: 1 | T3: 1 | U3: 1 | V3: 1 | W3: 1 | X3: 1 | Y3: =X3+1 -> 2 | Z3: =Y3 -> 2 | AA3: =Z3 -> 2 | AB3: =AA3 -> 2 | AC3: =AB3 -> 2 | AD3: =AC3 -> 2 | AE3: =AD3 -> 2 | AF3: =AE3 -> 2 | AG3: =AF3 -> 2 | ... AJ3: =AI3 -> 2 | AK3: 3 | AL3: 3 | AM3: 3 | AN3: 3 | AO3: 3 | AP3: 3 | AQ3: 3 | AR3: 3 | AS3: 3 | AT3: 3 | AU3: 3 | AV3: 3 | AW3: 4 | AX3: 4 | AY3: 4 | AZ3: 4 | BA3: 4 | BB3: 4 | BC3: 4 | BD3: 4 | BE3: 4 | BF3: 4 | BG3: 4 | BH3: 4 | BI3: 5 | BJ3: 5 | BK3: 5 | BL3: 5 | BM3: 5 | BN3: 5 | BO3: 5 | BP3: 5 | BQ3: 5 | BR3: 5 | BS3: 5 | BT3: 5 | BV3: 1 | BW3: 2 | BX3: 3 | BY3: 4 | BZ3: 5
A4: Months | M4: 1 | N4: =M4+1 -> 2 | O4: =N4+1 -> 3 | P4: =O4+1 -> 4 | Q4: =P4+1 -> 5 | R4: =Q4+1 -> 6 | S4: =R4+1 -> 7 | T4: =S4+1 -> 8 | U4: =T4+1 -> 9 | ... BT4: =BS4+1 -> 60 | BV4: 12 | BW4: 24 | BX4: 36 | BY4: 48 | BZ4: 60
A5: SpoviX
A6: Qualified Leads | M6: =ROUND(Assumptions!M28/Assumptions!M29,0) -> 6 | N6: =ROUND(Assumptions!N28/Assumptions!N29,0) -> 6 | O6: =ROUND(Assumptions!O28/Assumptions!O29,0) -> 6 | P6: =ROUND(Assumptions!P28/Assumptions!P29,0) -> 6 | Q6: =ROUND(Assumptions!Q28/Assumptions!Q29,0) -> 6 | R6: =ROUND(Assumptions!R28/Assumptions!R29,0) -> 6 | S6: =ROUND(Assumptions!S28/Assumptions!S29,0) -> 6 | T6: =ROUND(Assumptions!T28/Assumptions!T29,0) -> 6 | ... BT6: =ROUND(Assumptions!BT28/Assumptions!BT29,0) -> 6 | BV6: =SUMIF($M$3:$BT$3,BV$3,$M6:$BT6) -> 72 | BW6: =SUMIF($M$3:$BT$3,BW$3,$M6:$BT6) -> 72 | BX6: =SUMIF($M$3:$BT$3,BX$3,$M6:$BT6) -> 72 | BY6: =SUMIF($M$3:$BT$3,BY$3,$M6:$BT6) -> 72 | BZ6: =SUMIF($M$3:$BT$3,BZ$3,$M6:$BT6) -> 72
A7: Active Customers
A8: New Clients | M8: =Assumptions!M10 -> 0 | N8: =Assumptions!N10 -> 0 | O8: =Assumptions!O10 -> 1 | P8: =Assumptions!P10 -> 0 | Q8: =Assumptions!Q10 -> 0 | R8: =Assumptions!R10 -> 1 | S8: =Assumptions!S10 -> 0 | T8: =Assumptions!T10 -> 0 | ... BT8: =Assumptions!BT10 -> 1 | BV8: =SUMIF($M$3:$BT$3,BV$3,$M8:$BT8) -> 4 | BW8: =SUMIF($M$3:$BT$3,BW$3,$M8:$BT8) -> 4 | BX8: =SUMIF($M$3:$BT$3,BX$3,$M8:$BT8) -> 2 | BY8: =SUMIF($M$3:$BT$3,BY$3,$M8:$BT8) -> 3 | BZ8: =SUMIF($M$3:$BT$3,BZ$3,$M8:$BT8) -> 6
A9: Existing Clients | M9: =Assumptions!G9 -> 1 | N9: =M11 -> 1 | O9: =N11 -> 1 | P9: =O11 -> 2 | Q9: =P11 -> 2 | R9: =Q11 -> 2 | S9: =R11 -> 3 | T9: =S11 -> 3 | U9: =T11 -> 3 | ... BT9: =BS11 -> 19 | BV9: =M9 -> 1 | BW9: =BV11 -> 5 | BX9: =BW11 -> 9 | BY9: =BX11 -> 11 | BZ9: =BY11 -> 14
A10: Churned | X10: =-ROUND(M8*Assumptions!X14,0) -> 0 | Y10: =-ROUND(N8*Assumptions!Y14,0) -> 0 | Z10: =-ROUND(O8*Assumptions!Z14,0) -> 0 | AA10: =-ROUND(P8*Assumptions!AA14,0) -> 0 | AB10: =-ROUND(Q8*Assumptions!AB14,0) -> 0 | AC10: =-ROUND(R8*Assumptions!AC14,0) -> 0 | AD10: =-ROUND(S8*Assumptions!AD14,0) -> 0 | AE10: =-ROUND(T8*Assumptions!AE14,0) -> 0 | ... BT10: =-ROUND(BI8*Assumptions!BT14,0) -> 0 | BV10: =SUMIF($M$3:$BT$3,BV$3,$M10:$BT10) -> 0 | BW10: =SUMIF($M$3:$BT$3,BW$3,$M10:$BT10) -> 0 | BX10: =SUMIF($M$3:$BT$3,BX$3,$M10:$BT10) -> 0 | BY10: =SUMIF($M$3:$BT$3,BY$3,$M10:$BT10) -> 0 | BZ10: =SUMIF($M$3:$BT$3,BZ$3,$M10:$BT10) -> 0
A11: Total Clients | M11: =SUM(M8:M10) -> 1 | N11: =SUM(N8:N10) -> 1 | O11: =SUM(O8:O10) -> 2 | P11: =SUM(P8:P10) -> 2 | Q11: =SUM(Q8:Q10) -> 2 | R11: =SUM(R8:R10) -> 3 | S11: =SUM(S8:S10) -> 3 | T11: =SUM(T8:T10) -> 3 | ... BT11: =SUM(BT8:BT10) -> 20 | BV11: =SUM(BV8:BV10) -> 5 | BW11: =SUM(BW8:BW10) -> 9 | BX11: =SUM(BX8:BX10) -> 11 | BY11: =SUM(BY8:BY10) -> 14 | BZ11: =SUM(BZ8:BZ10) -> 20
A12: Bookings
A13: New Bookings | M13: =M8*Assumptions!M11 -> 0 | N13: =N8*Assumptions!N11 -> 0 | O13: =O8*Assumptions!O11 -> 75000 | P13: =P8*Assumptions!P11 -> 0 | Q13: =Q8*Assumptions!Q11 -> 0 | R13: =R8*Assumptions!R11 -> 75000 | S13: =S8*Assumptions!S11 -> 0 | T13: =T8*Assumptions!T11 -> 0 | ... BT13: =BT8*Assumptions!BT11 -> 75000 | BV13: =SUMIF($M$3:$BT$3,BV$3,$M13:$BT13) -> 300000 | BW13: =SUMIF($M$3:$BT$3,BW$3,$M13:$BT13) -> 300000 | BX13: =SUMIF($M$3:$BT$3,BX$3,$M13:$BT13) -> 150000 | BY13: =SUMIF($M$3:$BT$3,BY$3,$M13:$BT13) -> 225000 | BZ13: =SUMIF($M$3:$BT$3,BZ$3,$M13:$BT13) -> 450000
A15: Revenue
A16: Revenue (MRR) | M16: =M11*Assumptions!M11/12 -> 6250 | N16: =N11*Assumptions!N11/12 -> 6250 | O16: =O11*Assumptions!O11/12 -> 12500 | P16: =P11*Assumptions!P11/12 -> 12500 | Q16: =Q11*Assumptions!Q11/12 -> 12500 | R16: =R11*Assumptions!R11/12 -> 18750 | S16: =S11*Assumptions!S11/12 -> 18750 | T16: =T11*Assumptions!T11/12 -> 18750 | ... BT16: =BT11*Assumptions!BT11/12 -> 125000 | BV16: =SUMIF($M$3:$BT$3,BV$3,$M16:$BT16) -> 212500 | BW16: =SUMIF($M$3:$BT$3,BW$3,$M16:$BT16) -> 512500 | BX16: =SUMIF($M$3:$BT$3,BX$3,$M16:$BT16) -> 725000 | BY16: =SUMIF($M$3:$BT$3,BY$3,$M16:$BT16) -> 918750 | BZ16: =SUMIF($M$3:$BT$3,BZ$3,$M16:$BT16) -> 1275000
A17: ARR | M17: =M16*12 -> 75000 | N17: =N16*12 -> 75000 | O17: =O16*12 -> 150000 | P17: =P16*12 -> 150000 | Q17: =Q16*12 -> 150000 | R17: =R16*12 -> 225000 | S17: =S16*12 -> 225000 | T17: =T16*12 -> 225000 | ... BT17: =BT16*12 -> 1500000

Sheet Cost Buildup
A1: Cost Buildup
A2: Cells in Orange are assumptions | M2: MONTHLY | BV2: YEARLY
A3: Year | M3: 1 | N3: 1 | O3: 1 | P3: 1 | Q3: 1 | R3: 1 | S3: 1 | T3: 1 | U3: 1 | V3: 1 | W3: 1 | X3: 1 | Y3: =X3+1 -> 2 | Z3: =Y3 -> 2 | AA3: =Z3 -> 2 | AB3: =AA3 -> 2 | AC3: =AB3 -> 2 | AD3: =AC3 -> 2 | AE3: =AD3 -> 2 | AF3: =AE3 -> 2 | AG3: =AF3 -> 2 | ... AJ3: =AI3 -> 2 | AK3: 3 | AL3: 3 | AM3: 3 | AN3: 3 | AO3: 3 | AP3: 3 | AQ3: 3 | AR3: 3 | AS3: 3 | AT3: 3 | AU3: 3 | AV3: 3 | AW3: 4 | AX3: 4 | AY3: 4 | AZ3: 4 | BA3: 4 | BB3: 4 | BC3: 4 | BD3: 4 | BE3: 4 | BF3: 4 | BG3: 4 | BH3: 4 | BI3: 5 | BJ3: 5 | BK3: 5 | BL3: 5 | BM3: 5 | BN3: 5 | BO3: 5 | BP3: 5 | BQ3: 5 | BR3: 5 | BS3: 5 | BT3: 5 | BV3: 1 | BW3: 2 | BX3: 3 | BY3: 4 | BZ3: 5
A4: Months | M4: 1 | N4: =M4+1 -> 2 | O4: =N4+1 -> 3 | P4: =O4+1 -> 4 | Q4: =P4+1 -> 5 | R4: =Q4+1 -> 6 | S4: =R4+1 -> 7 | T4: =S4+1 -> 8 | U4: =T4+1 -> 9 | ... BT4: =BS4+1 -> 60 | BV4: 12 | BW4: 24 | BX4: 36 | BY4: 48 | BZ4: 60
A5: =Assumptions!A17 -> Direct Cost
A6: =Assumptions!A18 -> Hosting & Infrastructure Costs | M6: =SUM(M7:M7) -> 375 | N6: =SUM(N7:N7) -> 375 | O6: =SUM(O7:O7) -> 750 | P6: =SUM(P7:P7) -> 750 | Q6: =SUM(Q7:Q7) -> 750 | R6: =SUM(R7:R7) -> 1125 | S6: =SUM(S7:S7) -> 1125 | T6: =SUM(T7:T7) -> 1125 | ... BT6: =SUM(BT7:BT7) -> 7500 | BV6: =SUMIF($M$3:$BT$3,BV$3,$M6:$BT6) -> 12750 | BW6: =SUMIF($M$3:$BT$3,BW$3,$M6:$BT6) -> 30750 | BX6: =SUMIF($M$3:$BT$3,BX$3,$M6:$BT6) -> 43500 | BY6: =SUMIF($M$3:$BT$3,BY$3,$M6:$BT6) -> 55125 | BZ6: =SUMIF($M$3:$BT$3,BZ$3,$M6:$BT6) -> 76500
A7: =Assumptions!A19 -> Hosting & Infrastructure Costs | M7: ='Revenue Buildup'!M16*Assumptions!M19 -> 375 | N7: ='Revenue Buildup'!N16*Assumptions!N19 -> 375 | O7: ='Revenue Buildup'!O16*Assumptions!O19 -> 750 | P7: ='Revenue Buildup'!P16*Assumptions!P19 -> 750 | Q7: ='Revenue Buildup'!Q16*Assumptions!Q19 -> 750 | R7: ='Revenue Buildup'!R16*Assumptions!R19 -> 1125 | S7: ='Revenue Buildup'!S16*Assumptions!S19 -> 1125 | T7: ='Revenue Buildup'!T16*Assumptions!T19 -> 1125 | ... BT7: ='Revenue Buildup'!BT16*Assumptions!BT19 -> 7500 | BV7: =SUMIF($M$3:$BT$3,BV$3,$M7:$BT7) -> 12750 | BW7: =SUMIF($M$3:$BT$3,BW$3,$M7:$BT7) -> 30750 | BX7: =SUMIF($M$3:$BT$3,BX$3,$M7:$BT7) -> 43500 | BY7: =SUMIF($M$3:$BT$3,BY$3,$M7:$BT7) -> 55125 | BZ7: =SUMIF($M$3:$BT$3,BZ$3,$M7:$BT7) -> 76500
A8: =Assumptions!A22 -> Headcount
A9: =Assumptions!A23 -> Customer Support | C9: Base | F9: =Assumptions!F23 -> Customer support/Account | G9: =Assumptions!G23 -> 5 | H9: =Assumptions!H23 -> 5 | M9: =Assumptions!M23 -> 5 | N9: =Assumptions!N23 -> 5 | O9: =Assumptions!O23 -> 5 | P9: =Assumptions!P23 -> 5 | Q9: =Assumptions!Q23 -> 5 | R9: =Assumptions!R23 -> 5 | S9: =Assumptions!S23 -> 5 | T9: =Assumptions!T23 -> 5 | ... BT9: =Assumptions!BT23 -> 5
A10: Customer Support | M10: =ROUND('Revenue Buildup'!M11/Assumptions!M23,0) -> 0 | N10: =ROUND('Revenue Buildup'!N11/Assumptions!N23,0) -> 0 | O10: =ROUND('Revenue Buildup'!O11/Assumptions!O23,0) -> 0 | P10: =ROUND('Revenue Buildup'!P11/Assumptions!P23,0) -> 0 | Q10: =ROUND('Revenue Buildup'!Q11/Assumptions!Q23,0) -> 0 | R10: =ROUND('Revenue Buildup'!R11/Assumptions!R23,0) -> 1 | S10: =ROUND('Revenue Buildup'!S11/Assumptions!S23,0) -> 1 | T10: =ROUND('Revenue Buildup'!T11/Assumptions!T23,0) -> 1 | ... BT10: =ROUND('Revenue Buildup'!BT11/Assumptions!BT23,0) -> 4
A11: Customer Support Team Salary
A12: =Assumptions!A24 -> Customer Support | F12: =Assumptions!F24 -> Monthly Salary | G12: =Assumptions!G24 -> 821.88564 | H12: =Assumptions!H24 -> 0.05 | I12: =Assumptions!I24 -> Annual Increment | M12: =(M10*$G$12)*(1+$H$12)^(M$3-1) -> 0 | N12: =(N10*$G$12)*(1+$H$12)^(N$3-1) -> 0 | O12: =(O10*$G$12)*(1+$H$12)^(O$3-1) -> 0 | P12: =(P10*$G$12)*(1+$H$12)^(P$3-1) -> 0 | Q12: =(Q10*$G$12)*(1+$H$12)^(Q$3-1) -> 0 | R12: =(R10*$G$12)*(1+$H$12)^(R$3-1) -> 821.88564 | S12: =(S10*$G$12)*(1+$H$12)^(S$3-1) -> 821.88564 | T12: =(T10*$G$12)*(1+$H$12)^(T$3-1) -> 821.88564 | ... BT12: =(BT10*$G$12)*(1+$H$12)^(BT$3-1) -> 3996.0285 | BV12: =SUMIF($M$3:$BT$3,BV$3,$M12:$BT12) -> 5753.1995 | BW12: =SUMIF($M$3:$BT$3,BW$3,$M12:$BT12) -> 13807.679 | BX12: =SUMIF($M$3:$BT$3,BX$3,$M12:$BT12) -> 21747.094 | BY12: =SUMIF($M$3:$BT$3,BY$3,$M12:$BT12) -> 27591.626 | BZ12: =SUMIF($M$3:$BT$3,BZ$3,$M12:$BT12) -> 40959.292
A13: Total Direct Cost | M13: =M7+M12 -> 375 | N13: =N7+N12 -> 375 | O13: =O7+O12 -> 750 | P13: =P7+P12 -> 750 | Q13: =Q7+Q12 -> 750 | R13: =R7+R12 -> 1946.8856 | S13: =S7+S12 -> 1946.8856 | T13: =T7+T12 -> 1946.8856 | ... BT13: =BT7+BT12 -> 11496.029 | BV13: =SUMIF($M$3:$BT$3,BV$3,$M13:$BT13) -> 18503.199 | BW13: =SUMIF($M$3:$BT$3,BW$3,$M13:$BT13) -> 44557.679 | BX13: =SUMIF($M$3:$BT$3,BX$3,$M13:$BT13) -> 65247.094 | BY13: =SUMIF($M$3:$BT$3,BY$3,$M13:$BT13) -> 82716.626 | BZ13: =SUMIF($M$3:$BT$3,BZ$3,$M13:$BT13) -> 117459.29
A14: =Assumptions!A25 -> Operating Expense
A15: =Assumptions!A26 -> Sales & Marketing Expense
A16: =Assumptions!A27 -> Sales
A17: =Assumptions!A28 -> Sales-SDR-Outsourced | M17: =Assumptions!M28 -> 1800 | N17: =Assumptions!N28 -> 1800 | O17: =Assumptions!O28 -> 1800 | P17: =Assumptions!P28 -> 1800 | Q17: =Assumptions!Q28 -> 1800 | R17: =Assumptions!R28 -> 1800 | S17: =Assumptions!S28 -> 1800 | T17: =Assumptions!T28 -> 1800 | ... BT17: =Assumptions!BT28 -> 1800 | BV17: =SUMIF($M$3:$BT$3,BV$3,$M17:$BT17) -> 21600 | BW17: =SUMIF($M$3:$BT$3,BW$3,$M17:$BT17) -> 21600 | BX17: =SUMIF($M$3:$BT$3,BX$3,$M17:$BT17) -> 21600 | BY17: =SUMIF($M$3:$BT$3,BY$3,$M17:$BT17) -> 21600 | BZ17: =SUMIF($M$3:$BT$3,BZ$3,$M17:$BT17) -> 21600
A18: =Assumptions!A29 -> Cost/Lead | M18: =Assumptions!M29 -> 300 | N18: =Assumptions!N29 -> 300 | O18: =Assumptions!O29 -> 300 | P18: =Assumptions!P29 -> 300 | Q18: =Assumptions!Q29 -> 300 | R18: =Assumptions!R29 -> 300 | S18: =Assumptions!S29 -> 300 | T18: =Assumptions!T29 -> 300 | ... BT18: =Assumptions!BT29 -> 300
A19: Qualified Leads | M19: =ROUND(M17/M18,0) -> 6 | N19: =ROUND(N17/N18,0) -> 6 | O19: =ROUND(O17/O18,0) -> 6 | P19: =ROUND(P17/P18,0) -> 6 | Q19: =ROUND(Q17/Q18,0) -> 6 | R19: =ROUND(R17/R18,0) -> 6 | S19: =ROUND(S17/S18,0) -> 6 | T19: =ROUND(T17/T18,0) -> 6 | ... BT19: =ROUND(BT17/BT18,0) -> 6
A20: =Assumptions!A30 -> Additional Cost for Qualified Leads | M20: =M19*Assumptions!M30 -> 1800 | N20: =N19*Assumptions!N30 -> 1800 | O20: =O19*Assumptions!O30 -> 1800 | P20: =P19*Assumptions!P30 -> 1800 | Q20: =Q19*Assumptions!Q30 -> 1800 | R20: =R19*Assumptions!R30 -> 1800 | S20: =S19*Assumptions!S30 -> 1800 | T20: =T19*Assumptions!T30 -> 1800 | ... BT20: =BT19*Assumptions!BT30 -> 1800
A21: =Assumptions!A31 -> Sales Commission %
A22: =Assumptions!A32 -> New Bookings | M22: =Assumptions!M32*'Revenue Buildup'!M13 -> 0 | N22: =Assumptions!N32*'Revenue Buildup'!N13 -> 0 | O22: =Assumptions!O32*'Revenue Buildup'!O13 -> 2250 | P22: =Assumptions!P32*'Revenue Buildup'!P13 -> 0 | Q22: =Assumptions!Q32*'Revenue Buildup'!Q13 -> 0 | R22: =Assumptions!R32*'Revenue Buildup'!R13 -> 2250 | S22: =Assumptions!S32*'Revenue Buildup'!S13 -> 0 | T22: =Assumptions!T32*'Revenue Buildup'!T13 -> 0 | ... BT22: =Assumptions!BT32*'Revenue Buildup'!BT13 -> 2250 | BV22: =SUMIF($M$3:$BT$3,BV$3,$M22:$BT22) -> 9000 | BW22: =SUMIF($M$3:$BT$3,BW$3,$M22:$BT22) -> 9000 | BX22: =SUMIF($M$3:$BT$3,BX$3,$M22:$BT22) -> 4500 | BY22: =SUMIF($M$3:$BT$3,BY$3,$M22:$BT22) -> 6750 | BZ22: =SUMIF($M$3:$BT$3,BZ$3,$M22:$BT22) -> 13500
A23: Total Commissions | M23: =SUM(M22:M22) -> 0 | N23: =SUM(N22:N22) -> 0 | O23: =SUM(O22:O22) -> 2250 | P23: =SUM(P22:P22) -> 0 | Q23: =SUM(Q22:Q22) -> 0 | R23: =SUM(R22:R22) -> 2250 | S23: =SUM(S22:S22) -> 0 | T23: =SUM(T22:T22) -> 0 | ... BT23: =SUM(BT22:BT22) -> 2250
A24: =Assumptions!A35 -> Sales Team-Headcount
A25: =Assumptions!A36 -> Client Success Manager | C25: Base | F25: =Assumptions!F36 -> Qualified Leads/CSM/Month | G25: =Assumptions!G36 -> 10 | H25: =Assumptions!H36 -> 10 | M25: =Assumptions!M36 -> 10 | N25: =Assumptions!N36 -> 10 | O25: =Assumptions!O36 -> 10 | P25: =Assumptions!P36 -> 10 | Q25: =Assumptions!Q36 -> 10 | R25: =Assumptions!R36 -> 10 | S25: =Assumptions!S36 -> 10 | T25: =Assumptions!T36 -> 10 | ... BT25: =Assumptions!BT36 -> 10
M26: =ROUND(M19/M25,0) -> 1 | N26: =ROUND(N19/N25,0) -> 1 | O26: =ROUND(O19/O25,0) -> 1 | P26: =ROUND(P19/P25,0) -> 1 | Q26: =ROUND(Q19/Q25,0) -> 1 | R26: =ROUND(R19/R25,0) -> 1 | S26: =ROUND(S19/S25,0) -> 1 | T26: =ROUND(T19/T25,0) -> 1 | ... BT26: =ROUND(BT19/BT25,0) -> 1
A27: =Assumptions!A38 -> Sales Team Salaries
A28: =Assumptions!A39 -> Client Success Manager | F28: =Assumptions!F39 -> Monthly Salary/Headcount | G28: =Assumptions!G39 -> 1200 | H28: =Assumptions!H39 -> 0.05 | I28: =Assumptions!I39 -> Annual Increment | M28: =($G28*M26)*(1+$H28)^(M$3-1) -> 1200 | N28: =($G28*N26)*(1+$H28)^(N$3-1) -> 1200 | O28: =($G28*O26)*(1+$H28)^(O$3-1) -> 1200 | P28: =($G28*P26)*(1+$H28)^(P$3-1) -> 1200 | Q28: =($G28*Q26)*(1+$H28)^(Q$3-1) -> 1200 | R28: =($G28*R26)*(1+$H28)^(R$3-1) -> 1200 | S28: =($G28*S26)*(1+$H28)^(S$3-1) -> 1200 | T28: =($G28*T26)*(1+$H28)^(T$3-1) -> 1200 | ... BT28: =($G28*BT26)*(1+$H28)^(BT$3-1) -> 1458.6075 | BV28: =SUMIF($M$3:$BT$3,BV$3,$M28:$BT28) -> 14400 | BW28: =SUMIF($M$3:$BT$3,BW$3,$M28:$BT28) -> 15120 | BX28: =SUMIF($M$3:$BT$3,BX$3,$M28:$BT28) -> 15876 | BY28: =SUMIF($M$3:$BT$3,BY$3,$M28:$BT28) -> 16669.8 | BZ28: =SUMIF($M$3:$BT$3,BZ$3,$M28:$BT28) -> 17503.29
A29: Total Sales Salary | M29: =SUM(M28:M28) -> 1200 | N29: =SUM(N28:N28) -> 1200 | O29: =SUM(O28:O28) -> 1200 | P29: =SUM(P28:P28) -> 1200 | Q29: =SUM(Q28:Q28) -> 1200 | R29: =SUM(R28:R28) -> 1200 | S29: =SUM(S28:S28) -> 1200 | T29: =SUM(T28:T28) -> 1200 | ... BT29: =SUM(BT28:BT28) -> 1458.6075 | BV29: =SUMIF($M$3:$BT$3,BV$3,$M29:$BT29) -> 14400 | BW29: =SUMIF($M$3:$BT$3,BW$3,$M29:$BT29) -> 15120 | BX29: =SUMIF($M$3:$BT$3,BX$3,$M29:$BT29) -> 15876 | BY29: =SUMIF($M$3:$BT$3,BY$3,$M29:$BT29) -> 16669.8 | BZ29: =SUMIF($M$3:$BT$3,BZ$3,$M29:$BT29) -> 17503.29
A30: Total Sales Expenses | M30: =SUM(M17,M20,M23,M29) -> 4800 | N30: =SUM(N17,N20,N23,N29) -> 4800 | O30: =SUM(O17,O20,O23,O29) -> 7050 | P30: =SUM(P17,P20,P23,P29) -> 4800 | Q30: =SUM(Q17,Q20,Q23,Q29) -> 4800 | R30: =SUM(R17,R20,R23,R29) -> 7050 | S30: =SUM(S17,S20,S23,S29) -> 4800 | T30: =SUM(T17,T20,T23,T29) -> 4800 | ... BT30: =SUM(BT17,BT20,BT23,BT29) -> 7308.6075 | BV30: =SUMIF($M$3:$BT$3,BV$3,$M30:$BT30) -> 66600 | BW30: =SUMIF($M$3:$BT$3,BW$3,$M30:$BT30) -> 67320 | BX30: =SUMIF($M$3:$BT$3,BX$3,$M30:$BT30) -> 63576 | BY30: =SUMIF($M$3:$BT$3,BY$3,$M30:$BT30) -> 66619.8 | BZ30: =SUMIF($M$3:$BT$3,BZ$3,$M30:$BT30) -> 74203.29
A31: =Assumptions!A41 -> Marketing
A32: =Assumptions!A42 -> Marketing Budget | M32: =Assumptions!M42 -> 600 | N32: =Assumptions!N42 -> 600 | O32: =Assumptions!O42 -> 600 | P32: =Assumptions!P42 -> 600 | Q32: =Assumptions!Q42 -> 600 | R32: =Assumptions!R42 -> 600 | S32: =Assumptions!S42 -> 600 | T32: =Assumptions!T42 -> 600 | ... BT32: =Assumptions!BT42 -> 840
A33: =Assumptions!A43 -> Marketing Team Roles & Headcount
A34: =Assumptions!A44 -> ABC | F34: =Assumptions!F44 -> Monthly Salary/Headcount | G34: =Assumptions!G44 -> 0 | H34: =Assumptions!H44 -> 0.05 | I34: =Assumptions!I44 -> Annual Increment | M34: =($G34*Assumptions!M44)*(1+'Cost Buildup'!$H34)^(M$3-1) -> 0 | N34: =($G34*Assumptions!N44)*(1+'Cost Buildup'!$H34)^(N$3-1) -> 0 | O34: =($G34*Assumptions!O44)*(1+'Cost Buildup'!$H34)^(O$3-1) -> 0 | P34: =($G34*Assumptions!P44)*(1+'Cost Buildup'!$H34)^(P$3-1) -> 0 | Q34: =($G34*Assumptions!Q44)*(1+'Cost Buildup'!$H34)^(Q$3-1) -> 0 | R34: =($G34*Assumptions!R44)*(1+'Cost Buildup'!$H34)^(R$3-1) -> 0 | S34: =($G34*Assumptions!S44)*(1+'Cost Buildup'!$H34)^(S$3-1) -> 0 | T34: =($G34*Assumptions!T44)*(1+'Cost Buildup'!$H34)^(T$3-1) -> 0 | ... BT34: =($G34*Assumptions!BT44)*(1+'Cost Buildup'!$H34)^(BT$3-1) -> 0 | BV34: =SUMIF($M$3:$BT$3,BV$3,$M34:$BT34) -> 0 | BW34: =SUMIF($M$3:$BT$3,BW$3,$M34:$BT34) -> 0 | BX34: =SUMIF($M$3:$BT$3,BX$3,$M34:$BT34) -> 0 | BY34: =SUMIF($M$3:$BT$3,BY$3,$M34:$BT34) -> 0 | BZ34: =SUMIF($M$3:$BT$3,BZ$3,$M34:$BT34) -> 0
A35: =Assumptions!A45 -> ABC | F35: =Assumptions!F45 -> Monthly Salary/Headcount | G35: =Assumptions!G45 -> 0 | H35: =Assumptions!H45 -> 0.05 | I35: =Assumptions!I45 -> Annual Increment | M35: =($G35*Assumptions!M45)*(1+'Cost Buildup'!$H35)^(M$3-1) -> 0 | N35: =($G35*Assumptions!N45)*(1+'Cost Buildup'!$H35)^(N$3-1) -> 0 | O35: =($G35*Assumptions!O45)*(1+'Cost Buildup'!$H35)^(O$3-1) -> 0 | P35: =($G35*Assumptions!P45)*(1+'Cost Buildup'!$H35)^(P$3-1) -> 0 | Q35: =($G35*Assumptions!Q45)*(1+'Cost Buildup'!$H35)^(Q$3-1) -> 0 | R35: =($G35*Assumptions!R45)*(1+'Cost Buildup'!$H35)^(R$3-1) -> 0 | S35: =($G35*Assumptions!S45)*(1+'Cost Buildup'!$H35)^(S$3-1) -> 0 | T35: =($G35*Assumptions!T45)*(1+'Cost Buildup'!$H35)^(T$3-1) -> 0 | ... BT35: =($G35*Assumptions!BT45)*(1+'Cost Buildup'!$H35)^(BT$3-1) -> 0 | BV35: =SUMIF($M$3:$BT$3,BV$3,$M35:$BT35) -> 0 | BW35: =SUMIF($M$3:$BT$3,BW$3,$M35:$BT35) -> 0 | BX35: =SUMIF($M$3:$BT$3,BX$3,$M35:$BT35) -> 0 | BY35: =SUMIF($M$3:$BT$3,BY$3,$M35:$BT35) -> 0 | BZ35: =SUMIF($M$3:$BT$3,BZ$3,$M35:$BT35) -> 0
A36: =Assumptions!A46 -> ABC | F36: =Assumptions!F46 -> Monthly Salary/Headcount | G36: =Assumptions!G46 -> 0 | H36: =Assumptions!H46 -> 0.05 | I36: =Assumptions!I46 -> Annual Increment | M36: =($G36*Assumptions!M46)*(1+'Cost Buildup'!$H36)^(M$3-1) -> 0 | N36: =($G36*Assumptions!N46)*(1+'Cost Buildup'!$H36)^(N$3-1) -> 0 | O36: =($G36*Assumptions!O46)*(1+'Cost Buildup'!$H36)^(O$3-1) -> 0 | P36: =($G36*Assumptions!P46)*(1+'Cost Buildup'!$H36)^(P$3-1) -> 0 | Q36: =($G36*Assumptions!Q46)*(1+'Cost Buildup'!$H36)^(Q$3-1) -> 0 | R36: =($G36*Assumptions!R46)*(1+'Cost Buildup'!$H36)^(R$3-1) -> 0 | S36: =($G36*Assumptions!S46)*(1+'Cost Buildup'!$H36)^(S$3-1) -> 0 | T36: =($G36*Assumptions!T46)*(1+'Cost Buildup'!$H36)^(T$3-1) -> 0 | ... BT36: =($G36*Assumptions!BT46)*(1+'Cost Buildup'!$H36)^(BT$3-1) -> 0 | BV36: =SUMIF($M$3:$BT$3,BV$3,$M36:$BT36) -> 0 | BW36: =SUMIF($M$3:$BT$3,BW$3,$M36:$BT36) -> 0 | BX36: =SUMIF($M$3:$BT$3,BX$3,$M36:$BT36) -> 0 | BY36: =SUMIF($M$3:$BT$3,BY$3,$M36:$BT36) -> 0 | BZ36: =SUMIF($M$3:$BT$3,BZ$3,$M36:$BT36) -> 0
A37: =Assumptions!A47 -> ABC | F37: =Assumptions!F47 -> Monthly Salary/Headcount | G37: =Assumptions!G47 -> 0 | H37: =Assumptions!H47 -> 0.05 | I37: =Assumptions!I47 -> Annual Increment | M37: =($G37*Assumptions!M47)*(1+'Cost Buildup'!$H37)^(M$3-1) -> 0 | N37: =($G37*Assumptions!N47)*(1+'Cost Buildup'!$H37)^(N$3-1) -> 0 | O37: =($G37*Assumptions!O47)*(1+'Cost Buildup'!$H37)^(O$3-1) -> 0 | P37: =($G37*Assumptions!P47)*(1+'Cost Buildup'!$H37)^(P$3-1) -> 0 | Q37: =($G37*Assumptions!Q47)*(1+'Cost Buildup'!$H37)^(Q$3-1) -> 0 | R37: =($G37*Assumptions!R47)*(1+'Cost Buildup'!$H37)^(R$3-1) -> 0 | S37: =($G37*Assumptions!S47)*(1+'Cost Buildup'!$H37)^(S$3-1) -> 0 | T37: =($G37*Assumptions!T47)*(1+'Cost Buildup'!$H37)^(T$3-1) -> 0 | ... BT37: =($G37*Assumptions!BT47)*(1+'Cost Buildup'!$H37)^(BT$3-1) -> 0 | BV37: =SUMIF($M$3:$BT$3,BV$3,$M37:$BT37) -> 0 | BW37: =SUMIF($M$3:$BT$3,BW$3,$M37:$BT37) -> 0 | BX37: =SUMIF($M$3:$BT$3,BX$3,$M37:$BT37) -> 0 | BY37: =SUMIF($M$3:$BT$3,BY$3,$M37:$BT37) -> 0 | BZ37: =SUMIF($M$3:$BT$3,BZ$3,$M37:$BT37) -> 0
A38: =Assumptions!A48 -> ABC | F38: =Assumptions!F48 -> Monthly Salary/Headcount
A39: =Assumptions!A49 -> ABC | F39: =Assumptions!F49 -> Monthly Salary/Headcount
A40: Total Marketing Salary | M40: =SUM(M34:M37) -> 0 | N40: =SUM(N34:N37) -> 0 | O40: =SUM(O34:O37) -> 0 | P40: =SUM(P34:P37) -> 0 | Q40: =SUM(Q34:Q37) -> 0 | R40: =SUM(R34:R37) -> 0 | S40: =SUM(S34:S37) -> 0 | T40: =SUM(T34:T37) -> 0 | ... BT40: =SUM(BT34:BT37) -> 0 | BV40: =SUMIF($M$3:$BT$3,BV$3,$M40:$BT40) -> 0 | BW40: =SUMIF($M$3:$BT$3,BW$3,$M40:$BT40) -> 0 | BX40: =SUMIF($M$3:$BT$3,BX$3,$M40:$BT40) -> 0 | BY40: =SUMIF($M$3:$BT$3,BY$3,$M40:$BT40) -> 0 | BZ40: =SUMIF($M$3:$BT$3,BZ$3,$M40:$BT40) -> 0
...

Sheet FAS
A1: Fixed Asset Schedule
A2: Cells in Orange are assumptions | M2: MONTHLY | BV2: YEARLY
A3: Year | M3: 1 | N3: 1 | O3: 1 | P3: 1 | Q3: 1 | R3: 1 | S3: 1 | T3: 1 | U3: 1 | V3: 1 | W3: 1 | X3: 1 | Y3: =X3+1 -> 2 | Z3: =Y3 -> 2 | AA3: =Z3 -> 2 | AB3: =AA3 -> 2 | AC3: =AB3 -> 2 | AD3: =AC3 -> 2 | AE3: =AD3 -> 2 | AF3: =AE3 -> 2 | AG3: =AF3 -> 2 | ... AJ3: =AI3 -> 2 | AK3: 3 | AL3: 3 | AM3: 3 | AN3: 3 | AO3: 3 | AP3: 3 | AQ3: 3 | AR3: 3 | AS3: 3 | AT3: 3 | AU3: 3 | AV3: 3 | AW3: 4 | AX3: 4 | AY3: 4 | AZ3: 4 | BA3: 4 | BB3: 4 | BC3: 4 | BD3: 4 | BE3: 4 | BF3: 4 | BG3: 4 | BH3: 4 | BI3: 5 | BJ3: 5 | BK3: 5 | BL3: 5 | BM3: 5 | BN3: 5 | BO3: 5 | BP3: 5 | BQ3: 5 | BR3: 5 | BS3: 5 | BT3: 5 | BV3: 1 | BW3: 2 | BX3: 3 | BY3: 4 | BZ3: 5
A4: Months | M4: 1 | N4: =M4+1 -> 2 | O4: =N4+1 -> 3 | P4: =O4+1 -> 4 | Q4: =P4+1 -> 5 | R4: =Q4+1 -> 6 | S4: =R4+1 -> 7 | T4: =S4+1 -> 8 | U4: =T4+1 -> 9 | ... BT4: =BS4+1 -> 60 | BV4: 12 | BW4: 24 | BX4: 36 | BY4: 48 | BZ4: 60

Sheet IS
A1: Income Statement
A2: Cells in Orange are assumptions | M2: MONTHLY | BV2: YEARLY | CB2: Common Size Statement
A3: Year | M3: 1 | N3: 1 | O3: 1 | P3: 1 | Q3: 1 | R3: 1 | S3: 1 | T3: 1 | U3: 1 | V3: 1 | W3: 1 | X3: 1 | Y3: =X3+1 -> 2 | Z3: =Y3 -> 2 | AA3: =Z3 -> 2 | AB3: =AA3 -> 2 | AC3: =AB3 -> 2 | AD3: =AC3 -> 2 | AE3: =AD3 -> 2 | AF3: =AE3 -> 2 | AG3: =AF3 -> 2 | ... AJ3: =AI3 -> 2 | AK3: 3 | AL3: 3 | AM3: 3 | AN3: 3 | AO3: 3 | AP3: 3 | AQ3: 3 | AR3: 3 | AS3: 3 | AT3: 3 | AU3: 3 | AV3: 3 | AW3: 4 | AX3: 4 | AY3: 4 | AZ3: 4 | BA3: 4 | BB3: 4 | BC3: 4 | BD3: 4 | BE3: 4 | BF3: 4 | BG3: 4 | BH3: 4 | BI3: 5 | BJ3: 5 | BK3: 5 | BL3: 5 | BM3: 5 | BN3: 5 | BO3: 5 | BP3: 5 | BQ3: 5 | BR3: 5 | BS3: 5 | BT3: 5 | BV3: 1 | BW3: 2 | BX3: 3 | BY3: 4 | BZ3: 5 | CB3: 1 | CC3: 2 | CD3: 3 | CE3: 4 | CF3: 5
A4: Months | M4: 1 | N4: =M4+1 -> 2 | O4: =N4+1 -> 3 | P4: =O4+1 -> 4 | Q4: =P4+1 -> 5 | R4: =Q4+1 -> 6 | S4: =R4+1 -> 7 | T4: =S4+1 -> 8 | U4: =T4+1 -> 9 | ... BT4: =BS4+1 -> 60 | BV4: 12 | BW4: 24 | BX4: 36 | BY4: 48 | BZ4: 60 | CB4: 12 | CC4: 24 | CD4: 36 | CE4: 48 | CF4: 60
A5: Revenues
B6: Active Clients | M6: ='Revenue Buildup'!M11 -> 1 | N6: ='Revenue Buildup'!N11 -> 1 | O6: ='Revenue Buildup'!O11 -> 2 | P6: ='Revenue Buildup'!P11 -> 2 | Q6: ='Revenue Buildup'!Q11 -> 2 | R6: ='Revenue Buildup'!R11 -> 3 | S6: ='Revenue Buildup'!S11 -> 3 | T6: ='Revenue Buildup'!T11 -> 3 | ... BT6: ='Revenue Buildup'!BT11 -> 20 | BV6: =INDEX($M6:$BT6,MATCH(BV$4,$M$4:$BT$4,0)) -> 5 | BW6: =INDEX($M6:$BT6,MATCH(BW$4,$M$4:$BT$4,0)) -> 9 | BX6: =INDEX($M6:$BT6,MATCH(BX$4,$M$4:$BT$4,0)) -> 11 | BY6: =INDEX($M6:$BT6,MATCH(BY$4,$M$4:$BT$4,0)) -> 14 | BZ6: =INDEX($M6:$BT6,MATCH(BZ$4,$M$4:$BT$4,0)) -> 20
A7: [+] | B7: Revenue | M7: ='Revenue Buildup'!M16 -> 6250 | N7: ='Revenue Buildup'!N16 -> 6250 | O7: ='Revenue Buildup'!O16 -> 12500 | P7: ='Revenue Buildup'!P16 -> 12500 | Q7: ='Revenue Buildup'!Q16 -> 12500 | R7: ='Revenue Buildup'!R16 -> 18750 | S7: ='Revenue Buildup'!S16 -> 18750 | T7: ='Revenue Buildup'!T16 -> 18750 | ... BT7: ='Revenue Buildup'!BT16 -> 125000 | BV7: =SUMIF($M$3:$BT$3,BV$3,$M7:$BT7) -> 212500 | BW7: =SUMIF($M$3:$BT$3,BW$3,$M7:$BT7) -> 512500 | BX7: =SUMIF($M$3:$BT$3,BX$3,$M7:$BT7) -> 725000 | BY7: =SUMIF($M$3:$BT$3,BY$3,$M7:$BT7) -> 918750 | BZ7: =SUMIF($M$3:$BT$3,BZ$3,$M7:$BT7) -> 1275000 | CB7: =BV7/BV$7 -> 1 | CC7: =BW7/BW$7 -> 1 | CD7: =BX7/BX$7 -> 1 | CE7: =BY7/BY$7 -> 1 | CF7: =BZ7/BZ$7 -> 1
A8: Direct Expenses
A9: [-] | B9: ='Cost Buildup'!A6 -> Hosting & Infrastructure Costs | M9: ='Cost Buildup'!M6 -> 375 | N9: ='Cost Buildup'!N6 -> 375 | O9: ='Cost Buildup'!O6 -> 750 | P9: ='Cost Buildup'!P6 -> 750 | Q9: ='Cost Buildup'!Q6 -> 750 | R9: ='Cost Buildup'!R6 -> 1125 | S9: ='Cost Buildup'!S6 -> 1125 | T9: ='Cost Buildup'!T6 -> 1125 | ... BT9: ='Cost Buildup'!BT6 -> 7500 | BV9: =SUMIF($M$3:$BT$3,BV$3,$M9:$BT9) -> 12750 | BW9: =SUMIF($M$3:$BT$3,BW$3,$M9:$BT9) -> 30750 | BX9: =SUMIF($M$3:$BT$3,BX$3,$M9:$BT9) -> 43500 | BY9: =SUMIF($M$3:$BT$3,BY$3,$M9:$BT9) -> 55125 | BZ9: =SUMIF($M$3:$BT$3,BZ$3,$M9:$BT9) -> 76500 | CB9: =BV9/BV$7 -> 0.06 | CC9: =BW9/BW$7 -> 0.06 | CD9: =BX9/BX$7 -> 0.06 | CE9: =BY9/BY$7 -> 0.06 | CF9: =BZ9/BZ$7 -> 0.06
A10: [-] | B10: ='Cost Buildup'!A12 -> Customer Support | M10: ='Cost Buildup'!M12 -> 0 | N10: ='Cost Buildup'!N12 -> 0 | O10: ='Cost Buildup'!O12 -> 0 | P10: ='Cost Buildup'!P12 -> 0 | Q10: ='Cost Buildup'!Q12 -> 0 | R10: ='Cost Buildup'!R12 -> 821.88564 | S10: ='Cost Buildup'!S12 -> 821.88564 | T10: ='Cost Buildup'!T12 -> 821.88564 | ... BT10: ='Cost Buildup'!BT12 -> 3996.0285 | BV10: =SUMIF($M$3:$BT$3,BV$3,$M10:$BT10) -> 5753.1995 | BW10: =SUMIF($M$3:$BT$3,BW$3,$M10:$BT10) -> 13807.679 | BX10: =SUMIF($M$3:$BT$3,BX$3,$M10:$BT10) -> 21747.094 | BY10: =SUMIF($M$3:$BT$3,BY$3,$M10:$BT10) -> 27591.626 | BZ10: =SUMIF($M$3:$BT$3,BZ$3,$M10:$BT10) -> 40959.292 | CB10: =BV10/BV$7 -> 0.02707388 | CC10: =BW10/BW$7 -> 0.026941812 | CD10: =BX10/BX$7 -> 0.029995992 | CE10: =BY10/BY$7 -> 0.030031701 | CF10: =BZ10/BZ$7 -> 0.032124935
A11: COGS | M11: =SUM(M9:M10) -> 375 | N11: =SUM(N9:N10) -> 375 | O11: =SUM(O9:O10) -> 750 | P11: =SUM(P9:P10) -> 750 | Q11: =SUM(Q9:Q10) -> 750 | R11: =SUM(R9:R10) -> 1946.8856 | S11: =SUM(S9:S10) -> 1946.8856 | T11: =SUM(T9:T10) -> 1946.8856 | ... BT11: =SUM(BT9:BT10) -> 11496.029 | BV11: =SUMIF($M$3:$BT$3,BV$3,$M11:$BT11) -> 18503.199 | BW11: =SUMIF($M$3:$BT$3,BW$3,$M11:$BT11) -> 44557.679 | BX11: =SUMIF($M$3:$BT$3,BX$3,$M11:$BT11) -> 65247.094 | BY11: =SUMIF($M$3:$BT$3,BY$3,$M11:$BT11) -> 82716.626 | BZ11: =SUMIF($M$3:$BT$3,BZ$3,$M11:$BT11) -> 117459.29 | CB11: =BV11/BV$7 -> 0.08707388 | CC11: =BW11/BW$7 -> 0.086941812 | CD11: =BX11/BX$7 -> 0.089995992 | CE11: =BY11/BY$7 -> 0.090031701 | CF11: =BZ11/BZ$7 -> 0.092124935
B12: Gross Profit | M12: =M7-M11 -> 5875 | N12: =N7-N11 -> 5875 | O12: =O7-O11 -> 11750 | P12: =P7-P11 -> 11750 | Q12: =Q7-Q11 -> 11750 | R12: =R7-R11 -> 16803.114 | S12: =S7-S11 -> 16803.114 | T12: =T7-T11 -> 16803.114 | ... BT12: =BT7-BT11 -> 113503.97 | BV12: =BV7-BV11 -> 193996.8 | BW12: =BW7-BW11 -> 467942.32 | BX12: =BX7-BX11 -> 659752.91 | BY12: =BY7-BY11 -> 836033.37 | BZ12: =BZ7-BZ11 -> 1157540.7 | CB12: =BV12/BV$7 -> 0.91292612 | CC12: =BW12/BW$7 -> 0.91305819 | CD12: =BX12/BX$7 -> 0.91000401 | CE12: =BY12/BY$7 -> 0.9099683 | CF12: =BZ12/BZ$7 -> 0.90787506
B13: Gross Profit % | M13: =M12/M$7 -> 0.94 | N13: =N12/N$7 -> 0.94 | O13: =O12/O$7 -> 0.94 | P13: =P12/P$7 -> 0.94 | Q13: =Q12/Q$7 -> 0.94 | R13: =R12/R$7 -> 0.8961661 | S13: =S12/S$7 -> 0.8961661 | T13: =T12/T$7 -> 0.8961661 | ... BT13: =BT12/BT$7 -> 0.90803177 | BV13: =BV12/BV$7 -> 0.91292612 | BW13: =BW12/BW$7 -> 0.91305819 | BX13: =BX12/BX$7 -> 0.91000401 | BY13: =BY12/BY$7 -> 0.9099683 | BZ13: =BZ12/BZ$7 -> 0.90787506
A14: Operating Expenses
A15: [+] | B15: Sales & Marketing | M15: ='Cost Buildup'!M17+'Cost Buildup'!M20+'Cost Buildup'!M23+'Cost Buildup'!M32 -> 4200 | N15: ='Cost Buildup'!N17+'Cost Buildup'!N20+'Cost Buildup'!N23+'Cost Buildup'!N32 -> 4200 | O15: ='Cost Buildup'!O17+'Cost Buildup'!O20+'Cost Buildup'!O23+'Cost Buildup'!O32 -> 6450 | P15: ='Cost Buildup'!P17+'Cost Buildup'!P20+'Cost Buildup'!P23+'Cost Buildup'!P32 -> 4200 | Q15: ='Cost Buildup'!Q17+'Cost Buildup'!Q20+'Cost Buildup'!Q23+'Cost Buildup'!Q32 -> 4200 | R15: ='Cost Buildup'!R17+'Cost Buildup'!R20+'Cost Buildup'!R23+'Cost Buildup'!R32 -> 6450 | S15: ='Cost Buildup'!S17+'Cost Buildup'!S20+'Cost Buildup'!S23+'Cost Buildup'!S32 -> 4200 | T15: ='Cost Buildup'!T17+'Cost Buildup'!T20+'Cost Buildup'!T23+'Cost Buildup'!T32 -> 4200 | ... BT15: ='Cost Buildup'!BT17+'Cost Buildup'!BT20+'Cost Buildup'!BT23+'Cost Buildup'!BT32 -> 6690 | BV15: =SUMIF($M$3:$BT$3,BV$3,$M15:$BT15) -> 59400 | BW15: =SUMIF($M$3:$BT$3,BW$3,$M15:$BT15) -> 59400 | BX15: =SUMIF($M$3:$BT$3,BX$3,$M15:$BT15) -> 57780 | BY15: =SUMIF($M$3:$BT$3,BY$3,$M15:$BT15) -> 60030 | BZ15: =SUMIF($M$3:$BT$3,BZ$3,$M15:$BT15) -> 66780 | CB15: =BV15/BV$7 -> 0.27952941 | CC15: =BW15/BW$7 -> 0.11590244 | CD15: =BX15/BX$7 -> 0.079696552 | CE15: =BY15/BY$7 -> 0.065338776 | CF15: =BZ15/BZ$7 -> 0.052376471
A16: [+] | B16: G&A | M16: =SUM('Cost Buildup'!M43:M45) -> 4414.7 | N16: =SUM('Cost Buildup'!N43:N45) -> 4425.2001 | O16: =SUM('Cost Buildup'!O43:O45) -> 4435.7002 | P16: =SUM('Cost Buildup'!P43:P45) -> 4446.2002 | Q16: =SUM('Cost Buildup'!Q43:Q45) -> 4456.7003 | R16: =SUM('Cost Buildup'!R43:R45) -> 4612.1336 | S16: =SUM('Cost Buildup'!S43:S45) -> 4769.1822 | T16: =SUM('Cost Buildup'!T43:T45) -> 4781.2977 | ... BT16: =SUM('Cost Buildup'!BT43:BT45) -> 7862.4374 | BV16: =SUMIF($M$3:$BT$3,BV$3,$M16:$BT16) -> 55587.46 | BW16: =SUMIF($M$3:$BT$3,BW$3,$M16:$BT16) -> 63255.868 | BX16: =SUMIF($M$3:$BT$3,BX$3,$M16:$BT16) -> 66745.897 | BY16: =SUMIF($M$3:$BT$3,BY$3,$M16:$BT16) -> 71649.462 | BZ16: =SUMIF($M$3:$BT$3,BZ$3,$M16:$BT16) -> 80059.628 | CB16: =BV16/BV$7 -> 0.26158805 | CC16: =BW16/BW$7 -> 0.12342608 | CD16: =BX16/BX$7 -> 0.092063306 | CE16: =BY16/BY$7 -> 0.077985809 | CF16: =BZ16/BZ$7 -> 0.062791865
A17: [+] | B17: Product Development (Infra) | M17: ='Cost Buildup'!M55 -> 1585.0652 | N17: ='Cost Buildup'!N55 -> 1616.7665 | O17: ='Cost Buildup'!O55 -> 1649.1018 | P17: ='Cost Buildup'!P55 -> 1682.0838 | Q17: ='Cost Buildup'!Q55 -> 1715.7255 | R17: ='Cost Buildup'!R55 -> 1750.04 | S17: ='Cost Buildup'!S55 -> 1785.0408 | T17: ='Cost Buildup'!T55 -> 1820.7416 | ... BT17: ='Cost Buildup'!BT55 -> 5098.6741 | BV17: =SUMIF($M$3:$BT$3,BV$3,$M17:$BT17) -> 21259.036 | BW17: =SUMIF($M$3:$BT$3,BW$3,$M17:$BT17) -> 26961.598 | BX17: =SUMIF($M$3:$BT$3,BX$3,$M17:$BT17) -> 34193.826 | BY17: =SUMIF($M$3:$BT$3,BY$3,$M17:$BT17) -> 43366.039 | BZ17: =SUMIF($M$3:$BT$3,BZ$3,$M17:$BT17) -> 54998.623 | CB17: =BV17/BV$7 -> 0.10004252 | CC17: =BW17/BW$7 -> 0.052607997 | CD17: =BX17/BX$7 -> 0.047163898 | CE17: =BY17/BY$7 -> 0.047201131 | CF17: =BZ17/BZ$7 -> 0.043136175
A18: [+] | B18: Employees Benefit Expense | M18: =SUM(M19:M22) -> 22206.399 | N18: =SUM(N19:N22) -> 22206.399 | O18: =SUM(O19:O22) -> 22206.399 | P18: =SUM(P19:P22) -> 22206.399 | Q18: =SUM(Q19:Q22) -> 22206.399 | R18: =SUM(R19:R22) -> 22206.399 | S18: =SUM(S19:S22) -> 22910.872 | T18: =SUM(T19:T22) -> 22910.872 | ... BT18: =SUM(BT19:BT22) -> 53358.53 | BV18: =SUMIF($M$3:$BT$3,BV$3,$M18:$BT18) -> 270703.63 | BW18: =SUMIF($M$3:$BT$3,BW$3,$M18:$BT18) -> 303887.38 | BX18: =SUMIF($M$3:$BT$3,BX$3,$M18:$BT18) -> 328000.71 | BY18: =SUMIF($M$3:$BT$3,BY$3,$M18:$BT18) -> 381297.78 | BZ18: =SUMIF($M$3:$BT$3,BZ$3,$M18:$BT18) -> 467986.97 | CB18: =BV18/BV$7 -> 1.2738994 | CC18: =BW18/BW$7 -> 0.59295099 | CD18: =BX18/BX$7 -> 0.45241477 | CE18: =BY18/BY$7 -> 0.41501799 | CF18: =BZ18/BZ$7 -> 0.36704861
A19: [+] | B19: Sales | M19: ='Cost Buildup'!M29 -> 1200 | N19: ='Cost Buildup'!N29 -> 1200 | O19: ='Cost Buildup'!O29 -> 1200 | P19: ='Cost Buildup'!P29 -> 1200 | Q19: ='Cost Buildup'!Q29 -> 1200 | R19: ='Cost Buildup'!R29 -> 1200 | S19: ='Cost Buildup'!S29 -> 1200 | T19: ='Cost Buildup'!T29 -> 1200 | ... BT19: ='Cost Buildup'!BT29 -> 1458.6075 | BV19: =SUMIF($M$3:$BT$3,BV$3,$M19:$BT19) -> 14400 | BW19: =SUMIF($M$3:$BT$3,BW$3,$M19:$BT19) -> 15120 | BX19: =SUMIF($M$3:$BT$3,BX$3,$M19:$BT19) -> 15876 | BY19: =SUMIF($M$3:$BT$3,BY$3,$M19:$BT19) -> 16669.8 | BZ19: =SUMIF($M$3:$BT$3,BZ$3,$M19:$BT19) -> 17503.29 | CB19: =BV19/BV$7 -> 0.067764706 | CC19: =BW19/BW$7 -> 0.029502439 | CD19: =BX19/BX$7 -> 0.021897931 | CE19: =BY19/BY$7 -> 0.018144 | CF19: =BZ19/BZ$7 -> 0.013728071
A20: [+] | B20: Marketing | M20: ='Cost Buildup'!M40 -> 0 | N20: ='Cost Buildup'!N40 -> 0 | O20: ='Cost Buildup'!O40 -> 0 | P20: ='Cost Buildup'!P40 -> 0 | Q20: ='Cost Buildup'!Q40 -> 0 | R20: ='Cost Buildup'!R40 -> 0 | S20: ='Cost Buildup'!S40 -> 0 | T20: ='Cost Buildup'!T40 -> 0 | ... BT20: ='Cost Buildup'!BT40 -> 0 | BV20: =SUMIF($M$3:$BT$3,BV$3,$M20:$BT20) -> 0 | BW20: =SUMIF($M$3:$BT$3,BW$3,$M20:$BT20) -> 0 | BX20: =SUMIF($M$3:$BT$3,BX$3,$M20:$BT20) -> 0 | BY20: =SUMIF($M$3:$BT$3,BY$3,$M20:$BT20) -> 0 | BZ20: =SUMIF($M$3:$BT$3,BZ$3,$M20:$BT20) -> 0 | CB20: =BV20/BV$7 -> 0 | CC20: =BW20/BW$7 -> 0 | CD20: =BX20/BX$7 -> 0 | CE20: =BY20/BY$7 -> 0 | CF20: =BZ20/BZ$7 -> 0
A21: [+] | B21: G&A | M21: ='Cost Buildup'!M52 -> 5929.3178 | N21: ='Cost Buildup'!N52 -> 5929.3178 | O21: ='Cost Buildup'!O52 -> 5929.3178 | P21: ='Cost Buildup'!P52 -> 5929.3178 | Q21: ='Cost Buildup'!Q52 -> 5929.3178 | R21: ='Cost Buildup'!R52 -> 5929.3178 | S21: ='Cost Buildup'!S52 -> 6633.7912 | T21: ='Cost Buildup'!T52 -> 6633.7912 | ... BT21: ='Cost Buildup'!BT52 -> 7751.2137 | BV21: =SUMIF($M$3:$BT$3,BV$3,$M21:$BT21) -> 75378.654 | BW21: =SUMIF($M$3:$BT$3,BW$3,$M21:$BT21) -> 89749.912 | BX21: =SUMIF($M$3:$BT$3,BX$3,$M21:$BT21) -> 90785.488 | BY21: =SUMIF($M$3:$BT$3,BY$3,$M21:$BT21) -> 91872.843 | BZ21: =SUMIF($M$3:$BT$3,BZ$3,$M21:$BT21) -> 93014.565 | CB21: =BV21/BV$7 -> 0.35472308 | CC21: =BW21/BW$7 -> 0.17512178 | CD21: =BX21/BX$7 -> 0.12522136 | CE21: =BY21/BY$7 -> 0.099997652 | CF21: =BZ21/BZ$7 -> 0.0729526
A22: [+] | B22: Product Development | M22: ='Cost Buildup'!M67 -> 15077.081 | N22: ='Cost Buildup'!N67 -> 15077.081 | O22: ='Cost Buildup'!O67 -> 15077.081 | P22: ='Cost Buildup'!P67 -> 15077.081 | Q22: ='Cost Buildup'!Q67 -> 15077.081 | R22: ='Cost Buildup'!R67 -> 15077.081 | S22: ='Cost Buildup'!S67 -> 15077.081 | T22: ='Cost Buildup'!T67 -> 15077.081 | ... BT22: ='Cost Buildup'!BT67 -> 44148.709 | BV22: =SUMIF($M$3:$BT$3,BV$3,$M22:$BT22) -> 180924.97 | BW22: =SUMIF($M$3:$BT$3,BW$3,$M22:$BT22) -> 199017.47 | BX22: =SUMIF($M$3:$BT$3,BX$3,$M22:$BT22) -> 221339.22 | BY22: =SUMIF($M$3:$BT$3,BY$3,$M22:$BT22) -> 272755.14 | BZ22: =SUMIF($M$3:$BT$3,BZ$3,$M22:$BT22) -> 357469.12 | CB22: =BV22/BV$7 -> 0.85141164 | CC22: =BW22/BW$7 -> 0.38832677 | CD22: =BX22/BX$7 -> 0.30529547 | CE22: =BY22/BY$7 -> 0.29687634 | CF22: =BZ22/BZ$7 -> 0.28036794
A23: Total Operating Expense | M23: =SUM(M15:M18) -> 32406.164 | N23: =SUM(N15:N18) -> 32448.366 | O23: =SUM(O15:O18) -> 34741.201 | P23: =SUM(P15:P18) -> 32534.683 | Q23: =SUM(Q15:Q18) -> 32578.825 | R23: =SUM(R15:R18) -> 35018.573 | S23: =SUM(S15:S18) -> 33665.095 | T23: =SUM(T15:T18) -> 33712.912 | ... BT23: =SUM(BT15:BT18) -> 73009.642 | BV23: =SUMIF($M$3:$BT$3,BV$3,$M23:$BT23) -> 406950.12 | BW23: =SUMIF($M$3:$BT$3,BW$3,$M23:$BT23) -> 453504.85 | BX23: =SUMIF($M$3:$BT$3,BX$3,$M23:$BT23) -> 486720.43 | BY23: =SUMIF($M$3:$BT$3,BY$3,$M23:$BT23) -> 556343.28 | BZ23: =SUMIF($M$3:$BT$3,BZ$3,$M23:$BT23) -> 669825.22 | CB23: =BV23/BV$7 -> 1.9150594 | CC23: =BW23/BW$7 -> 0.88488751 | CD23: =BX23/BX$7 -> 0.67133852 | CE23: =BY23/BY$7 -> 0.60554371 | CF23: =BZ23/BZ$7 -> 0.52535312
CB24: =BV24/BV$7 -> 0 | CC24: =BW24/BW$7 -> 0
B25: EBITDA | M25: =M12-M23 -> -26531.164 | N25: =N12-N23 -> -26573.366 | O25: =O12-O23 -> -22991.201 | P25: =P12-P23 -> -20784.683 | Q25: =Q12-Q23 -> -20828.825 | R25: =R12-R23 -> -18215.458 | S25: =S12-S23 -> -16861.981 | T25: =T12-T23 -> -16909.797 | ... BT25: =BT12-BT23 -> 40494.33 | BV25: =BV12-BV23 -> -212953.32 | BW25: =BW12-BW23 -> 14437.473 | BX25: =BX12-BX23 -> 173032.48 | BY25: =BY12-BY23 -> 279690.09 | BZ25: =BZ12-BZ23 -> 487715.48 | CB25: =BV25/BV$7 -> -1.0021333 | CC25: =BW25/BW$7 -> 0.028170678 | CD25: =BX25/BX$7 -> 0.23866549 | CE25: =BY25/BY$7 -> 0.30442459 | CF25: =BZ25/BZ$7 -> 0.38252195
B26: EBITDA% | M26: =M25/M$7 -> -4.2449863 | N26: =N25/N$7 -> -4.2517385 | O26: =O25/O$7 -> -1.8392961 | P26: =P25/P$7 -> -1.6627746 | Q26: =Q25/Q$7 -> -1.666306 | R26: =R25/R$7 -> -0.9714911 | S26: =S25/S$7 -> -0.89930566 | T26: =T25/T$7 -> -0.90185586 | ... BT26: =BT25/BT$7 -> 0.32395464 | BV26: =BV25/BV$7 -> -1.0021333 | BW26: =BW25/BW$7 -> 0.028170678 | BX26: =BX25/BX$7 -> 0.23866549 | BY26: =BY25/BY$7 -> 0.30442459 | BZ26: =BZ25/BZ$7 -> 0.38252195
A28: [-] | B28: Depreciation and Amortization | BV28: =SUMIF($M$3:$BT$3,BV$3,$M28:$BT28) -> 0 | BW28: =SUMIF($M$3:$BT$3,BW$3,$M28:$BT28) -> 0 | BX28: =SUMIF($M$3:$BT$3,BX$3,$M28:$BT28) -> 0 | BY28: =SUMIF($M$3:$BT$3,BY$3,$M28:$BT28) -> 0 | BZ28: =SUMIF($M$3:$BT$3,BZ$3,$M28:$BT28) -> 0 | CB28: =BV28/BV$7 -> 0 | CC28: =BW28/BW$7 -> 0 | CD28: =BX28/BX$7 -> 0 | CE28: =BY28/BY$7 -> 0 | CF28: =BZ28/BZ$7 -> 0
A29: [-] | B29: Interest Expense | BV29: =SUMIF($M$3:$BT$3,BV$3,$M29:$BT29) -> 0 | BW29: =SUMIF($M$3:$BT$3,BW$3,$M29:$BT29) -> 0 | BX29: =SUMIF($M$3:$BT$3,BX$3,$M29:$BT29) -> 0 | BY29: =SUMIF($M$3:$BT$3,BY$3,$M29:$BT29) -> 0 | BZ29: =SUMIF($M$3:$BT$3,BZ$3,$M29:$BT29) -> 0 | CB29: =BV29/BV$7 -> 0 | CC29: =BW29/BW$7 -> 0 | CD29: =BX29/BX$7 -> 0 | CE29: =BY29/BY$7 -> 0 | CF29: =BZ29/BZ$7 -> 0
B31: EBT | M31: =M25-M28-M29 -> -26531.164 | N31: =N25-N28-N29 -> -26573.366 | O31: =O25-O28-O29 -> -22991.201 | P31: =P25-P28-P29 -> -20784.683 | Q31: =Q25-Q28-Q29 -> -20828.825 | R31: =R25-R28-R29 -> -18215.458 | S31: =S25-S28-S29 -> -16861.981 | T31: =T25-T28-T29 -> -16909.797 | ... BT31: =BT25-BT28-BT29 -> 40494.33 | BV31: =BV25-BV28-BV29 -> -212953.32 | BW31: =BW25-BW28-BW29 -> 14437.473 | BX31: =BX25-BX28-BX29 -> 173032.48 | BY31: =BY25-BY28-BY29 -> 279690.09 | BZ31: =BZ25-BZ28-BZ29 -> 487715.48 | CB31: =BV31/BV$7 -> -1.0021333 | CC31: =BW31/BW$7 -> 0.028170678 | CD31: =BX31/BX$7 -> 0.23866549 | CE31: =BY31/BY$7 -> 0.30442459 | CF31: =BZ31/BZ$7 -> 0.38252195
B32: EBT % | M32: =M31/M$7 -> -4.2449863 | N32: =N31/N$7 -> -4.2517385 | O32: =O31/O$7 -> -1.8392961 | P32: =P31/P$7 -> -1.6627746 | Q32: =Q31/Q$7 -> -1.666306 | R32: =R31/R$7 -> -0.9714911 | S32: =S31/S$7 -> -0.89930566 | T32: =T31/T$7 -> -0.90185586 | ... BT32: =BT31/BT$7 -> 0.32395464 | BV32: =BV31/BV$7 -> -1.0021333 | BW32: =BW31/BW$7 -> 0.028170678 | BX32: =BX31/BX$7 -> 0.23866549 | BY32: =BY31/BY$7 -> 0.30442459 | BZ32: =BZ31/BZ$7 -> 0.38252195
A33: [-] | B33: Tax Expense | F33: 0.25 | BV33: =SUMIF($M$3:$BT$3,BV$3,$M33:$BT33) -> 0 | BW33: =SUMIF($M$3:$BT$3,BW$3,$M33:$BT33) -> 0 | BX33: =SUMIF($M$3:$BT$3,BX$3,$M33:$BT33) -> 0 | BY33: =SUMIF($M$3:$BT$3,BY$3,$M33:$BT33) -> 0 | BZ33: =SUMIF($M$3:$BT$3,BZ$3,$M33:$BT33) -> 0 | CB33: =BV33/BV$7 -> 0 | CC33: =BW33/BW$7 -> 0 | CD33: =BX33/BX$7 -> 0 | CE33: =BY33/BY$7 -> 0 | CF33: =BZ33/BZ$7 -> 0
B35: EAT | M35: =M31-M33 -> -26531.164 | N35: =N31-N33 -> -26573.366 | O35: =O31-O33 -> -22991.201 | P35: =P31-P33 -> -20784.683 | Q35: =Q31-Q33 -> -20828.825 | R35: =R31-R33 -> -18215.458 | S35: =S31-S33 -> -16861.981 | T35: =T31-T33 -> -16909.797 | ... BT35: =BT31-BT33 -> 40494.33 | BV35: =BV31-BV33 -> -212953.32 | BW35: =BW31-BW33 -> 14437.473 | BX35: =BX31-BX33 -> 173032.48 | BY35: =BY31-BY33 -> 279690.09 | BZ35: =BZ31-BZ33 -> 487715.48 | CB35: =BV35/BV$7 -> -1.0021333 | CC35: =BW35/BW$7 -> 0.028170678 | CD35: =BX35/BX$7 -> 0.23866549 | CE35: =BY35/BY$7 -> 0.30442459 | CF35: =BZ35/BZ$7 -> 0.38252195
B36: EAT% | M36: =M35/M$7 -> -4.2449863 | N36: =N35/N$7 -> -4.2517385 | O36: =O35/O$7 -> -1.8392961 | P36: =P35/P$7 -> -1.6627746 | Q36: =Q35/Q$7 -> -1.666306 | R36: =R35/R$7 -> -0.9714911 | S36: =S35/S$7 -> -0.89930566 | T36: =T35/T$7 -> -0.90185586 | ... BT36: =BT35/BT$7 -> 0.32395464 | BV36: =BV35/BV$7 -> -1.0021333 | BW36: =BW35/BW$7 -> 0.028170678 | BX36: =BX35/BX$7 -> 0.23866549 | BY36: =BY35/BY$7 -> 0.30442459 | BZ36: =BZ35/BZ$7 -> 0.38252195
A39: Treatment of Tax
A40: Taxable Income
A41: Cumulative Taxable Income

Sheet BS
A1: Balance Sheet
A2: Cells in Orange are assumptions | M2: MONTHLY | BV2: YEARLY
A3: Year | M3: 1 | N3: 1 | O3: 1 | P3: 1 | Q3: 1 | R3: 1 | S3: 1 | T3: 1 | U3: 1 | V3: 1 | W3: 1 | X3: 1 | Y3: =X3+1 -> 2 | Z3: =Y3 -> 2 | AA3: =Z3 -> 2 | AB3: =AA3 -> 2 | AC3: =AB3 -> 2 | AD3: =AC3 -> 2 | AE3: =AD3 -> 2 | AF3: =AE3 -> 2 | AG3: =AF3 -> 2 | ... AJ3: =AI3 -> 2 | AK3: 3 | AL3: 3 | AM3: 3 | AN3: 3 | AO3: 3 | AP3: 3 | AQ3: 3 | AR3: 3 | AS3: 3 | AT3: 3 | AU3: 3 | AV3: 3 | AW3: 4 | AX3: 4 | AY3: 4 | AZ3: 4 | BA3: 4 | BB3: 4 | BC3: 4 | BD3: 4 | BE3: 4 | BF3: 4 | BG3: 4 | BH3: 4 | BI3: 5 | BJ3: 5 | BK3: 5 | BL3: 5 | BM3: 5 | BN3: 5 | BO3: 5 | BP3: 5 | BQ3: 5 | BR3: 5 | BS3: 5 | BT3: 5 | BV3: 1 | BW3: 2 | BX3: 3 | BY3: 4 | BZ3: 5
A4: Months | M4: 1 | N4: =M4+1 -> 2 | O4: =N4+1 -> 3 | P4: =O4+1 -> 4 | Q4: =P4+1 -> 5 | R4: =Q4+1 -> 6 | S4: =R4+1 -> 7 | T4: =S4+1 -> 8 | U4: =T4+1 -> 9 | ... BT4: =BS4+1 -> 60 | BV4: 12 | BW4: 24 | BX4: 36 | BY4: 48 | BZ4: 60
A5: I. Equity & Liabilities
A6: Shareholders' Fund
A7: [+] | B7: Share Capital
A8: [+] | B8: Reserves & Surplus | M8: =L8+IS!M35 -> -26531.164 | N8: =M8+IS!N35 -> -53104.53 | O8: =N8+IS!O35 -> -76095.731 | P8: =O8+IS!P35 -> -96880.414 | Q8: =P8+IS!Q35 -> -117709.24 | R8: =Q8+IS!R35 -> -135924.7 | S8: =R8+IS!S35 -> -152786.68 | T8: =S8+IS!T35 -> -169696.47 | ... BT8: =BS8+IS!BT35 -> 741922.2 | BV8: =INDEX($M8:$BT8,MATCH(BV$4,$M$4:$BT$4,0)) -> -212953.32 | BW8: =INDEX($M8:$BT8,MATCH(BW$4,$M$4:$BT$4,0)) -> -198515.85 | BX8: =INDEX($M8:$BT8,MATCH(BX$4,$M$4:$BT$4,0)) -> -25483.374 | BY8: =INDEX($M8:$BT8,MATCH(BY$4,$M$4:$BT$4,0)) -> 254206.72 | BZ8: =INDEX($M8:$BT8,MATCH(BZ$4,$M$4:$BT$4,0)) -> 741922.2
B9: TOTAL Shareholders Funds | M9: =SUM(M7:M8) -> -26531.164 | N9: =SUM(N7:N8) -> -53104.53 | O9: =SUM(O7:O8) -> -76095.731 | P9: =SUM(P7:P8) -> -96880.414 | Q9: =SUM(Q7:Q8) -> -117709.24 | R9: =SUM(R7:R8) -> -135924.7 | S9: =SUM(S7:S8) -> -152786.68 | T9: =SUM(T7:T8) -> -169696.47 | ... BT9: =SUM(BT7:BT8) -> 741922.2 | BV9: =INDEX($M9:$BT9,MATCH(BV$4,$M$4:$BT$4,0)) -> -212953.32 | BW9: =INDEX($M9:$BT9,MATCH(BW$4,$M$4:$BT$4,0)) -> -198515.85 | BX9: =INDEX($M9:$BT9,MATCH(BX$4,$M$4:$BT$4,0)) -> -25483.374 | BY9: =INDEX($M9:$BT9,MATCH(BY$4,$M$4:$BT$4,0)) -> 254206.72 | BZ9: =INDEX($M9:$BT9,MATCH(BZ$4,$M$4:$BT$4,0)) -> 741922.2
A11: Liabilities
A12: Non-current liabilities
B13: Long-term borrowings | BV13: =INDEX($M13:$BT13,MATCH(BV$4,$M$4:$BT$4,0)) -> 0 | BW13: =INDEX($M13:$BT13,MATCH(BW$4,$M$4:$BT$4,0)) -> 0 | BX13: =INDEX($M13:$BT13,MATCH(BX$4,$M$4:$BT$4,0)) -> 0 | BY13: =INDEX($M13:$BT13,MATCH(BY$4,$M$4:$BT$4,0)) -> 0 | BZ13: =INDEX($M13:$BT13,MATCH(BZ$4,$M$4:$BT$4,0)) -> 0
A14: Current Liabilities
A15: [+] | B15: Deferred Revenue
A16: [+] | B16: Trade Payables | BV16: =INDEX($M16:$BT16,MATCH(BV$4,$M$4:$BT$4,0)) -> 0 | BW16: =INDEX($M16:$BT16,MATCH(BW$4,$M$4:$BT$4,0)) -> 0 | BX16: =INDEX($M16:$BT16,MATCH(BX$4,$M$4:$BT$4,0)) -> 0 | BY16: =INDEX($M16:$BT16,MATCH(BY$4,$M$4:$BT$4,0)) -> 0 | BZ16: =INDEX($M16:$BT16,MATCH(BZ$4,$M$4:$BT$4,0)) -> 0
A17: [+] | B17: Other current liabilities | BV17: =INDEX($M17:$BT17,MATCH(BV$4,$M$4:$BT$4,0)) -> 0 | BW17: =INDEX($M17:$BT17,MATCH(BW$4,$M$4:$BT$4,0)) -> 0 | BX17: =INDEX($M17:$BT17,MATCH(BX$4,$M$4:$BT$4,0)) -> 0 | BY17: =INDEX($M17:$BT17,MATCH(BY$4,$M$4:$BT$4,0)) -> 0 | BZ17: =INDEX($M17:$BT17,MATCH(BZ$4,$M$4:$BT$4,0)) -> 0
B18: TOTAL Liabilities | M18: =SUM(M13,M15:M17) -> 0 | N18: =SUM(N13,N15:N17) -> 0 | O18: =SUM(O13,O15:O17) -> 0 | P18: =SUM(P13,P15:P17) -> 0 | Q18: =SUM(Q13,Q15:Q17) -> 0 | R18: =SUM(R13,R15:R17) -> 0 | S18: =SUM(S13,S15:S17) -> 0 | T18: =SUM(T13,T15:T17) -> 0 | ... BT18: =SUM(BT13,BT15:BT17) -> 0 | BV18: =INDEX($M18:$BT18,MATCH(BV$4,$M$4:$BT$4,0)) -> 0 | BW18: =INDEX($M18:$BT18,MATCH(BW$4,$M$4:$BT$4,0)) -> 0 | BX18: =INDEX($M18:$BT18,MATCH(BX$4,$M$4:$BT$4,0)) -> 0 | BY18: =INDEX($M18:$BT18,MATCH(BY$4,$M$4:$BT$4,0)) -> 0 | BZ18: =INDEX($M18:$BT18,MATCH(BZ$4,$M$4:$BT$4,0)) -> 0
B20: TOTAL Equity and Liabilities | M20: =M9+M18 -> -26531.164 | N20: =N9+N18 -> -53104.53 | O20: =O9+O18 -> -76095.731 | P20: =P9+P18 -> -96880.414 | Q20: =Q9+Q18 -> -117709.24 | R20: =R9+R18 -> -135924.7 | S20: =S9+S18 -> -152786.68 | T20: =T9+T18 -> -169696.47 | ... BT20: =BT9+BT18 -> 741922.2 | BV20: =BV9+BV18 -> -212953.32 | BW20: =BW9+BW18 -> -198515.85 | BX20: =BX9+BX18 -> -25483.374 | BY20: =BY9+BY18 -> 254206.72 | BZ20: =BZ9+BZ18 -> 741922.2
A22: II. Assets
A23: Non-Current Assets
A24: Fixed Assets
A25: [+] | B25: Tangible assets | BV25: =INDEX($M25:$BT25,MATCH(BV$4,$M$4:$BT$4,0)) -> 0 | BW25: =INDEX($M25:$BT25,MATCH(BW$4,$M$4:$BT$4,0)) -> 0 | BX25: =INDEX($M25:$BT25,MATCH(BX$4,$M$4:$BT$4,0)) -> 0 | BY25: =INDEX($M25:$BT25,MATCH(BY$4,$M$4:$BT$4,0)) -> 0 | BZ25: =INDEX($M25:$BT25,MATCH(BZ$4,$M$4:$BT$4,0)) -> 0
A26: [+] | B26: Intangible assets | BV26: =INDEX($M26:$BT26,MATCH(BV$4,$M$4:$BT$4,0)) -> 0 | BW26: =INDEX($M26:$BT26,MATCH(BW$4,$M$4:$BT$4,0)) -> 0 | BX26: =INDEX($M26:$BT26,MATCH(BX$4,$M$4:$BT$4,0)) -> 0 | BY26: =INDEX($M26:$BT26,MATCH(BY$4,$M$4:$BT$4,0)) -> 0 | BZ26: =INDEX($M26:$BT26,MATCH(BZ$4,$M$4:$BT$4,0)) -> 0
A27: [+] | B27: Other Non Current Asset | BV27: =INDEX($M27:$BT27,MATCH(BV$4,$M$4:$BT$4,0)) -> 0 | BW27: =INDEX($M27:$BT27,MATCH(BW$4,$M$4:$BT$4,0)) -> 0 | BX27: =INDEX($M27:$BT27,MATCH(BX$4,$M$4:$BT$4,0)) -> 0 | BY27: =INDEX($M27:$BT27,MATCH(BY$4,$M$4:$BT$4,0)) -> 0 | BZ27: =INDEX($M27:$BT27,MATCH(BZ$4,$M$4:$BT$4,0)) -> 0
B28: Total Non Current Assets | M28: =SUM(M25:M27) -> 0 | N28: =SUM(N25:N27) -> 0 | O28: =SUM(O25:O27) -> 0 | P28: =SUM(P25:P27) -> 0 | Q28: =SUM(Q25:Q27) -> 0 | R28: =SUM(R25:R27) -> 0 | S28: =SUM(S25:S27) -> 0 | T28: =SUM(T25:T27) -> 0 | ... BT28: =SUM(BT25:BT27) -> 0 | BV28: =SUM(BV25:BV27) -> 0 | BW28: =SUM(BW25:BW27) -> 0 | BX28: =SUM(BX25:BX27) -> 0 | BY28: =SUM(BY25:BY27) -> 0 | BZ28: =SUM(BZ25:BZ27) -> 0
A30: Current Assets
A31: [+] | B31: Trade Receivables | BV31: =INDEX($M31:$BT31,MATCH(BV$4,$M$4:$BT$4,0)) -> 0 | BW31: =INDEX($M31:$BT31,MATCH(BW$4,$M$4:$BT$4,0)) -> 0 | BX31: =INDEX($M31:$BT31,MATCH(BX$4,$M$4:$BT$4,0)) -> 0 | BY31: =INDEX($M31:$BT31,MATCH(BY$4,$M$4:$BT$4,0)) -> 0 | BZ31: =INDEX($M31:$BT31,MATCH(BZ$4,$M$4:$BT$4,0)) -> 0
A32: [+] | B32: Inventory | BV32: =INDEX($M32:$BT32,MATCH(BV$4,$M$4:$BT$4,0)) -> 0 | BW32: =INDEX($M32:$BT32,MATCH(BW$4,$M$4:$BT$4,0)) -> 0 | BX32: =INDEX($M32:$BT32,MATCH(BX$4,$M$4:$BT$4,0)) -> 0 | BY32: =INDEX($M32:$BT32,MATCH(BY$4,$M$4:$BT$4,0)) -> 0 | BZ32: =INDEX($M32:$BT32,MATCH(BZ$4,$M$4:$BT$4,0)) -> 0
A33: [+] | B33: Cash and Cash Equivalents | M33: =CFS!M43 -> -26531.164 | N33: =CFS!N43 -> -53104.53 | O33: =CFS!O43 -> -76095.731 | P33: =CFS!P43 -> -96880.414 | Q33: =CFS!Q43 -> -117709.24 | R33: =CFS!R43 -> -135924.7 | S33: =CFS!S43 -> -152786.68 | T33: =CFS!T43 -> -169696.47 | ... BT33: =CFS!BT43 -> 741922.2 | BV33: =INDEX($M33:$BT33,MATCH(BV$4,$M$4:$BT$4,0)) -> -212953.32 | BW33: =INDEX($M33:$BT33,MATCH(BW$4,$M$4:$BT$4,0)) -> -198515.85 | BX33: =INDEX($M33:$BT33,MATCH(BX$4,$M$4:$BT$4,0)) -> -25483.374 | BY33: =INDEX($M33:$BT33,MATCH(BY$4,$M$4:$BT$4,0)) -> 254206.72 | BZ33: =INDEX($M33:$BT33,MATCH(BZ$4,$M$4:$BT$4,0)) -> 741922.2
A34: [+] | B34: Short Term Loans and Advances | BV34: =INDEX($M34:$BT34,MATCH(BV$4,$M$4:$BT$4,0)) -> 0 | BW34: =INDEX($M34:$BT34,MATCH(BW$4,$M$4:$BT$4,0)) -> 0 | BX34: =INDEX($M34:$BT34,MATCH(BX$4,$M$4:$BT$4,0)) -> 0 | BY34: =INDEX($M34:$BT34,MATCH(BY$4,$M$4:$BT$4,0)) -> 0 | BZ34: =INDEX($M34:$BT34,MATCH(BZ$4,$M$4:$BT$4,0)) -> 0
B35: Total Current Assets | M35: =SUM(M31:M34) -> -26531.164 | N35: =SUM(N31:N34) -> -53104.53 | O35: =SUM(O31:O34) -> -76095.731 | P35: =SUM(P31:P34) -> -96880.414 | Q35: =SUM(Q31:Q34) -> -117709.24 | R35: =SUM(R31:R34) -> -135924.7 | S35: =SUM(S31:S34) -> -152786.68 | T35: =SUM(T31:T34) -> -169696.47 | ... BT35: =SUM(BT31:BT34) -> 741922.2 | BV35: =SUM(BV31:BV34) -> -212953.32 | BW35: =SUM(BW31:BW34) -> -198515.85 | BX35: =SUM(BX31:BX34) -> -25483.374 | BY35: =SUM(BY31:BY34) -> 254206.72 | BZ35: =SUM(BZ31:BZ34) -> 741922.2
B37: Total Assets | M37: =M28+M35 -> -26531.164 | N37: =N28+N35 -> -53104.53 | O37: =O28+O35 -> -76095.731 | P37: =P28+P35 -> -96880.414 | Q37: =Q28+Q35 -> -117709.24 | R37: =R28+R35 -> -135924.7 | S37: =S28+S35 -> -152786.68 | T37: =T28+T35 -> -169696.47 | ... BT37: =BT28+BT35 -> 741922.2 | BV37: =BV28+BV35 -> -212953.32 | BW37: =BW28+BW35 -> -198515.85 | BX37: =BX28+BX35 -> -25483.374 | BY37: =BY28+BY35 -> 254206.72 | BZ37: =BZ28+BZ35 -> 741922.2
